Workbook

Sheet Inputs
A1: Inputs
A3: Category | B3: Input | C3: Value | D3: Units / Note
A4: Raw Materials | B4: Aggregate purchase basis | C4: MT | D4: MT or CFT
A5: Raw Materials | B5: Aggregate purchase rate | C5: 380 | D5: ₹/MT or ₹/CFT
A6: Raw Materials | B6: Aggregate loose bulk density | C6: 1.5 | D6: MT/cum
A7: Raw Materials | B7: CFT per CUM | C7: 35.3147 | D7: constant
A8: Raw Materials | B8: Aggregate base rate at crusher (₹/MT) | C8: =IF(C4="MT",C5,C5*C7/C6) -> 380 | D8: derived
A9: Raw Materials | B9: Crusher to plant distance | C9: 12 | D9: km one way
A10: Raw Materials | B10: Crusher transport rate | C10: 95 | D10: ₹/km/load
A11: Raw Materials | B11: Crusher payload | C11: 28 | D11: MT
A12: Raw Materials | B12: Crusher to plant freight (₹/MT) | C12: =C9*2*C10/C11 -> 81.428571 | D12: derived | E12: =C9*2*C10 -> 2280
A13: Raw Materials | B13: Landed aggregate rate at plant (₹/MT) | C13: =C8+C12 -> 461.42857 | D13: derived
A14: Raw Materials | B14: Bitumen price | C14: 51 | D14: ₹/kg
A15: Mix | B15: BC binder content | C15: 0.054 | D15: fraction of mix
A16: Mix | B16: DBM binder content | C16: 0.033 | D16: fraction of mix
A17: Mix | B17: BC compacted density | C17: 2.35 | D17: MT/cum
A18: Mix | B18: DBM compacted density | C18: 2.3 | D18: MT/cum
A19: Plant | B19: Costing production rate | C19: 100 | D19: TPH
A20: Plant | B20: Plant operating hours per month | C20: 150 | D20: hours/month
A21: Plant | B21: Plant capex (incl. installation/civil) | C21: 30000000 | D21: ₹
A22: Plant | B22: Plant life | C22: 8 | D22: years
A23: Plant | B23: Plant maintenance | C23: 0.2 | D23: % of depreciation
A24: DG | B24: DG capex | C24: 2000000 | D24: ₹
A25: DG | B25: DG life | C25: 3 | D25: years
... A45: Crew | B45: Crew work hours per day | C45: 10 | D45: hours/day
A46: Commercial | B46: Margin / profit | D46: fraction on plant cost
A47: Transport | B47: Mix transport distance | C47: 77 | D47: km one way
A48: Transport | B48: Mix transport rate | C48: 95 | D48: ₹/km/load
A49: Transport | B49: Mix payload | C49: 32 | D49: MT
A50: Transport | B50: Mix transport cost per MT | C50: =C47*2*C48/C49 -> 457.1875 | D50: derived
A51: Paving & Rolling | B51: Paver hire | C51: 20000 | D51: ₹/day | E51: =11*C30*8 -> 8448
A52: Paving & Rolling | B52: Tandem roller hire | C52: 12000 | D52: ₹/day
A53: Paving & Rolling | B53: PTR hire | D53: ₹/day
A54: Paving & Rolling | B54: Crew | C54: 12000 | D54: ₹/day
A55: Paving & Rolling | B55: Diesel | C55: 18000 | D55: ₹/day
A56: Paving & Rolling | B56: Productivity | C56: =C42 -> 350 | D56: MT/day
A57: Paving & Rolling | B57: Paving & rolling cost per MT | C57: 0.7 | D57: derived
A58: Prime/Tack | B58: Prime coat spray rate | C58: 0.5 | D58: kg/sqm
A59: Prime/Tack | B59: Tack coat spray rate | C59: 0.12 | D59: kg/sqm
A60: Prime/Tack | B60: Prime emulsion price | C60: 61 | D60: ₹/kg
...

Sheet Mix Design
A1: Mix Design - BC and DBM
A3: Component | B3: BC % of mix | C3: DBM % of mix | D3: BC qty / 1 MT | E3: DBM qty / 1 MT | F3: BC qty / 1 CUM | G3: DBM qty / 1 CUM
A4: 20mm aggregate | C4: 0.2 | D4: =B4 -> 0 | E4: =C4 -> 0.2 | F4: =B4*Inputs!C17 -> 0 | G4: =C4*Inputs!C18 -> 0.46
A5: 10mm aggregate | B5: 0.174 | C5: 0.25 | D5: =B5 -> 0.174 | E5: =C5 -> 0.25 | F5: =B5*Inputs!C17 -> 0.4089 | G5: =C5*Inputs!C18 -> 0.575
A6: 6mm / chips | B6: 0.25 | C6: 0.1 | D6: =B6 -> 0.25 | E6: =C6 -> 0.1 | F6: =B6*Inputs!C17 -> 0.5875 | G6: =C6*Inputs!C18 -> 0.23
A7: Dust | B7: 0.522 | C7: 0.417 | D7: =B7 -> 0.522 | E7: =C7 -> 0.417 | F7: =B7*Inputs!C17 -> 1.2267 | G7: =C7*Inputs!C18 -> 0.9591
A8: Filler | D8: =B8 -> 0 | E8: =C8 -> 0 | F8: =B8*Inputs!C17 -> 0 | G8: =C8*Inputs!C18 -> 0
A9: Bitumen | B9: =Inputs!C15 -> 0.054 | C9: =Inputs!C16 -> 0.033 | D9: =B9 -> 0.054 | E9: =C9 -> 0.033 | F9: =B9*Inputs!C17 -> 0.1269 | G9: =C9*Inputs!C18 -> 0.0759
A10: Total | B10: =SUM(B4:B9) -> 1 | C10: =SUM(C4:C9) -> 1 | D10: =SUM(D4:D9) -> 1 | E10: =SUM(E4:E9) -> 1 | F10: =SUM(F4:F9) -> 2.35 | G10: =SUM(G4:G9) -> 2.3
A12: Note | B12: Edit BC/DBM composition if you have exact JMF. Bitumen rows are linked to Inputs.

Sheet Rate Model
A1: Rate Model - per MT and per Cum
A3: Cost Head | B3: Basis / Formula | C3: BC (₹/MT) | D3: BC (₹/cum) | E3: DBM (₹/MT) | F3: DBM (₹/cum) | G3: Notes / Surface
A4: Aggregate material | B4: Landed agg rate/MT × (1-binder%) | C4: =Inputs!$C$13*(1-Inputs!$C$15) -> 436.51143 | D4: =C4*Inputs!$C$17 -> 1025.8019 | E4: =Inputs!$C$13*(1-Inputs!$C$16) -> 446.20143 | F4: =E4*Inputs!$C$18 -> 1026.2633 | G4: Crusher+freight landed
A5: Bitumen | B5: Bitumen ₹/kg × 1000 × binder% | C5: =Inputs!$C$14*1000*Inputs!$C$15 -> 2754 | D5: =C5*Inputs!$C$17 -> 6471.9 | E5: =Inputs!$C$14*1000*Inputs!$C$16 -> 1683 | F5: =E5*Inputs!$C$18 -> 3870.9
A6: Plant depreciation + maintenance | B6: Plant capex/life × (1+maint) /12 /hours /TPH | C6: =Inputs!$C$21/Inputs!$C$22*(1+Inputs!$C$23)/12/Inputs!$C$20/Inputs!$C$19 -> 25 | D6: =C6*Inputs!$C$17 -> 58.75 | E6: =Inputs!$C$21/Inputs!$C$22*(1+Inputs!$C$23)/12/Inputs!$C$20/Inputs!$C$19 -> 25 | F6: =E6*Inputs!$C$18 -> 57.5
A7: DG depreciation + maintenance | B7: DG capex/life × (1+maint) /12 /hours /TPH | C7: =Inputs!$C$24/Inputs!$C$25*(1+Inputs!$C$26)/12/Inputs!$C$20/Inputs!$C$19 -> 4.2592593 | D7: =C7*Inputs!$C$17 -> 10.009259 | E7: =Inputs!$C$24/Inputs!$C$25*(1+Inputs!$C$26)/12/Inputs!$C$20/Inputs!$C$19 -> 4.2592593 | F7: =E7*Inputs!$C$18 -> 9.7962963
A8: JCB hire | B8: Monthly hire / billed hours / TPH | C8: =Inputs!$C$27/Inputs!$C$28/Inputs!$C$19 -> 4.1666667 | D8: =C8*Inputs!$C$17 -> 9.7916667 | E8: =Inputs!$C$27/Inputs!$C$28/Inputs!$C$19 -> 4.1666667 | F8: =E8*Inputs!$C$18 -> 9.5833333
A9: HSD for aggregate handling | B9: L/hr × ₹/L / TPH | C9: =Inputs!$C$29*Inputs!$C$30/Inputs!$C$19 -> 4.8 | D9: =C9*Inputs!$C$17 -> 11.28 | E9: =Inputs!$C$29*Inputs!$C$30/Inputs!$C$19 -> 4.8 | F9: =E9*Inputs!$C$18 -> 11.04
A10: Tipper inter-carting | B10: ₹/day / hours / TPH | C10: =Inputs!$C$31/Inputs!$C$32/Inputs!$C$19 -> 4.375 | D10: =C10*Inputs!$C$17 -> 10.28125 | E10: =Inputs!$C$31/Inputs!$C$32/Inputs!$C$19 -> 4.375 | F10: =E10*Inputs!$C$18 -> 10.0625
A11: P&R HSD | B11: L/hr × ₹/L / TPH | C11: =Inputs!$C$33*Inputs!$C$30/Inputs!$C$19 -> 6.72 | D11: =C11*Inputs!$C$17 -> 15.792 | E11: =Inputs!$C$33*Inputs!$C$30/Inputs!$C$19 -> 6.72 | F11: =E11*Inputs!$C$18 -> 15.456
A12: DG HSD | B12: L/hr × ₹/L / TPH | C12: =Inputs!$C$34*Inputs!$C$30/Inputs!$C$19 -> 72 | D12: =C12*Inputs!$C$17 -> 169.2 | E12: =Inputs!$C$34*Inputs!$C$30/Inputs!$C$19 -> 72 | F12: =E12*Inputs!$C$18 -> 165.6
A13: Dryer LDO | B13: L/MT × ₹/L | C13: =Inputs!$C$35*Inputs!$C$36 -> 310 | D13: =C13*Inputs!$C$17 -> 728.5 | E13: =Inputs!$C$35*Inputs!$C$36 -> 310 | F13: =E13*Inputs!$C$18 -> 713
A14: Boiler during production | B14: L/hr × ₹/L × prod hrs / campaign MT | C14: =Inputs!$C$37*Inputs!$C$39*Inputs!$C$40/Inputs!$C$42 -> 15.942857 | D14: =C14*Inputs!$C$17 -> 37.465714 | E14: =Inputs!$C$37*Inputs!$C$39*Inputs!$C$40/Inputs!$C$42 -> 15.942857 | F14: =E14*Inputs!$C$18 -> 36.668571
A15: Boiler preheating | B15: L/hr × ₹/L × preheat hrs / campaign MT | C15: =Inputs!$C$38*Inputs!$C$39*Inputs!$C$41/Inputs!$C$42 -> 23.382857 | D15: =C15*Inputs!$C$17 -> 54.949714 | E15: =Inputs!$C$38*Inputs!$C$39*Inputs!$C$41/Inputs!$C$42 -> 23.382857 | F15: =E15*Inputs!$C$18 -> 53.780571
A16: Crew | B16: Monthly crew / workdays / hours / TPH | C16: =Inputs!$C$43/Inputs!$C$44/Inputs!$C$45/Inputs!$C$19 -> 6.6666667 | D16: =C16*Inputs!$C$17 -> 15.666667 | E16: =Inputs!$C$43/Inputs!$C$44/Inputs!$C$45/Inputs!$C$19 -> 6.6666667 | F16: =E16*Inputs!$C$18 -> 15.333333
A17: Total cost before margin | B17: Sum above | C17: =SUM(C4:C16) -> 3667.8247 | D17: =C17*Inputs!$C$17 -> 8619.3881 | E17: =SUM(E4:E16) -> 2606.5147 | F17: =E17*Inputs!$C$18 -> 5994.9839
A18: Margin | B18: Total before margin × margin % | C18: =C17*Inputs!$C$46 -> 0 | D18: =C18*Inputs!$C$17 -> 0 | E18: =E17*Inputs!$C$46 -> 0 | F18: =E18*Inputs!$C$18 -> 0
A19: Final plant selling rate | B19: Cost + margin | C19: =C17+C18 -> 3667.8247 | D19: =C19*Inputs!$C$17 -> 8619.3881 | E19: =E17+E18 -> 2606.5147 | F19: =E19*Inputs!$C$18 -> 5994.9839 | G19: Ex-plant mix
A20: Mix transport to site | B20: Distance × 2 × rate ÷ payload | C20: =Inputs!$C$50 -> 457.1875 | D20: =C20*Inputs!$C$17 -> 1074.3906 | E20: =Inputs!$C$50 -> 457.1875 | F20: =E20*Inputs!$C$18 -> 1051.5312 | G20: Calculated from inputs
A21: Paving & rolling | B21: Daily cost ÷ productivity | C21: =Inputs!$C$57 -> 0.7 | D21: =C21*Inputs!$C$17 -> 1.645 | E21: =Inputs!$C$57 -> 0.7 | F21: =E21*Inputs!$C$18 -> 1.61
A22: Final laid rate | B22: Plant mix + transport + P&R | C22: =SUM(C19:C21) -> 4125.7122 | D22: =C22*Inputs!$C$17 -> 9695.4238 | E22: =SUM(E19:E21) -> 3064.4022 | F22: =E22*Inputs!$C$18 -> 7048.1251 | G22: Excl. prime/tack
A23: Prime spray operation | G23: =Inputs!$C$68 -> 1.1
A24: Prime material | G24: =Inputs!$C$69 -> 30.6
A25: Prime total cost / sqm | G25: =Inputs!$C$71 -> 31.7
A26: Tack spray operation | G26: =Inputs!$C$68 -> 1.1
A27: Tack material | G27: =Inputs!$C$70 -> 7.344
A28: Tack total cost / sqm | G28: =Inputs!$C$72 -> 8.444

Sheet Job Planner
A1: Job Planner
A2: Blue cells are inputs. Use GEOMETRY when Length/Width/Thickness are known. Use BOQ_CUM when only BOQ volume is given; length will be derived automatically from volume ÷ (width × thickness).
A3: Job ID | B3: Contractor | C3: Layer | D3: Qty Basis | E3: Length Input (m) | F3: Width (m) | G3: Thickness (mm) | H3: BOQ Qty (cum) | I3: Final Qty (cum) | J3: Area (sqm) | K3: Derived Length (m) | L3: Binder % | M3: Density (MT/cum) | N3: Mix Qty (MT) | O3: Bitumen (MT) | P3: Aggregates (MT) | Q3: Agg Qty (CFT) | R3: Plant Rate / MT | S3: Plant Amount | T3: Lead to Site (km) | U3: Truck ₹/km | V3: Return Factor | W3: Payload (MT) | X3: Extra / trip | Y3: Transport / MT | Z3: Transport Amount | AA3: P&R / MT | AB3: P&R Amount | AC3: Prime? 1/0 | AD3: Tack? 1/0 | AE3: Prime Amount | AF3: Tack Amount | AG3: Total Amount | AH3: Rate / MT | AI3: Rate / CUM | AJ3: Rate / SQM
A4: J01 | B4: Murthy | C4: DBM | D4: BOQ_CUM | E4: 1100 | F4: 5.5 | G4: 50 | H4: 57.75 | I4: =IF(D4="GEOMETRY",IF(AND(E4>0,F4>0,G4>0),E4*F4*(G4/1000),""),IF(AND(H4>0,G4>0),H4,"")) -> 57.75 | J4: =IF(AND(I4>0,G4>0),I4/(G4/1000),"") -> 1155 | K4: =IF(AND(J4>0,F4>0),J4/F4,"") -> 210 | L4: =IF(C4="BC",'Mix Design'!$B$9,IF(C4="DBM",'Mix Design'!$C$9,"")) -> 0.033 | M4: =IF(C4="BC",Inputs!$C$17,IF(C4="DBM",Inputs!$C$18,"")) -> 2.3 | N4: =IF(AND(I4>0,M4>0),I4*M4,"") -> 132.825 | O4: =IF(AND(N4>0,L4>0),N4*L4,"") -> 4.383225 | P4: =IF(AND(N4>0,O4>0),N4-O4,"") -> 128.44177 | Q4: =IF(AND(P4>0,Inputs!$C$6>0),P4/Inputs!$C$6*Inputs!$C$7,"") -> 3023.9218 | R4: =IF(C4="BC",'Rate Model'!$C$19,IF(C4="DBM",'Rate Model'!$E$19,"")) -> 2606.5147 | S4: =IF(AND(N4>0,R4>0),N4*R4,"") -> 346210.32 | T4: =IF(A4<>"",Inputs!$C$47,"") -> 77 | U4: =IF(A4<>"",Inputs!$C$48,"") -> 95 | V4: 2 | W4: =IF(A4<>"",Inputs!$C$49,"") -> 32 | X4: 0 | Y4: =IF(AND(T4>0,U4>0,V4>0,W4>0),((T4*U4*V4)+X4)/W4,"") -> 457.1875 | Z4: =IF(AND(N4>0,Y4>0),N4*Y4,"") -> 60725.93 | AA4: =IF(A4<>"",Inputs!$C$57,"") -> 0.7 | AB4: =IF(AND(N4>0,AA4>0),N4*AA4,"") -> 92.9775 | AC4: 1 | AD4: 0 | AE4: =IF(AND(J4>0,AC4>0),J4*AC4*Inputs!$C$71,0) -> 36613.5 | AF4: =IF(AND(J4>0,AD4>0),J4*AD4*Inputs!$C$72,0) -> 0 | AG4: =SUM(S4,Z4,AB4,AE4,AF4) -> 443642.73 | AH4: =IF(AND(N4>0,AG4>0),AG4/N4,"") -> 3340.0544 | AI4: =IF(AND(I4>0,AG4>0),AG4/I4,"") -> 7682.1251 | AJ4: =IF(AND(J4>0,AG4>0),AG4/J4,"") -> 384.10626
A5: J02 | B5: Murthy | C5: BC | D5: GEOMETRY | E5: 1100 | F5: 5.5 | G5: 30 | I5: =IF(D5="GEOMETRY",IF(AND(E5>0,F5>0,G5>0),E5*F5*(G5/1000),""),IF(AND(H5>0,G5>0),H5,"")) -> 181.5 | J5: =IF(AND(I5>0,G5>0),I5/(G5/1000),"") -> 6050 | K5: =IF(AND(J5>0,F5>0),J5/F5,"") -> 1100 | L5: =IF(C5="BC",'Mix Design'!$B$9,IF(C5="DBM",'Mix Design'!$C$9,"")) -> 0.054 | M5: =IF(C5="BC",Inputs!$C$17,IF(C5="DBM",Inputs!$C$18,"")) -> 2.35 | N5: =IF(AND(I5>0,M5>0),I5*M5,"") -> 426.525 | O5: =IF(AND(N5>0,L5>0),N5*L5,"") -> 23.03235 | P5: =IF(AND(N5>0,O5>0),N5-O5,"") -> 403.49265 | Q5: =IF(AND(P5>0,Inputs!$C$6>0),P5/Inputs!$C$6*Inputs!$C$7,"") -> 9499.4813 | R5: =IF(C5="BC",'Rate Model'!$C$19,IF(C5="DBM",'Rate Model'!$E$19,"")) -> 3667.8247 | S5: =IF(AND(N5>0,R5>0),N5*R5,"") -> 1564418.9 | T5: =IF(A5<>"",Inputs!$C$47,"") -> 77 | U5: =IF(A5<>"",Inputs!$C$48,"") -> 95 | V5: 2 | W5: =IF(A5<>"",Inputs!$C$49,"") -> 32 | X5: 0 | Y5: =IF(AND(T5>0,U5>0,V5>0,W5>0),((T5*U5*V5)+X5)/W5,"") -> 457.1875 | Z5: =IF(AND(N5>0,Y5>0),N5*Y5,"") -> 195001.9 | AA5: =IF(A5<>"",Inputs!$C$57,"") -> 0.7 | AB5: =IF(AND(N5>0,AA5>0),N5*AA5,"") -> 298.5675 | AC5: 0 | AD5: 1 | AE5: =IF(AND(J5>0,AC5>0),J5*AC5*Inputs!$C$71,0) -> 0 | AF5: =IF(AND(J5>0,AD5>0),J5*AD5*Inputs!$C$72,0) -> 51086.2 | AG5: =SUM(S5,Z5,AB5,AE5,AF5) -> 1810805.6 | AH5: =IF(AND(N5>0,AG5>0),AG5/N5,"") -> 4245.4853 | AI5: =IF(AND(I5>0,AG5>0),AG5/I5,"") -> 9976.8904 | AJ5: =IF(AND(J5>0,AG5>0),AG5/J5,"") -> 299.30671
A6: J03 | B6: Approach Contractor | C6: BC | D6: BOQ_CUM | F6: 5.5 | G6: 30 | H6: 180 | I6: =IF(D6="GEOMETRY",IF(AND(E6>0,F6>0,G6>0),E6*F6*(G6/1000),""),IF(AND(H6>0,G6>0),H6,"")) -> 180 | J6: =IF(AND(I6>0,G6>0),I6/(G6/1000),"") -> 6000 | K6: =IF(AND(J6>0,F6>0),J6/F6,"") -> 1090.9091 | L6: =IF(C6="BC",'Mix Design'!$B$9,IF(C6="DBM",'Mix Design'!$C$9,"")) -> 0.054 | M6: =IF(C6="BC",Inputs!$C$17,IF(C6="DBM",Inputs!$C$18,"")) -> 2.35 | N6: =IF(AND(I6>0,M6>0),I6*M6,"") -> 423 | O6: =IF(AND(N6>0,L6>0),N6*L6,"") -> 22.842 | P6: =IF(AND(N6>0,O6>0),N6-O6,"") -> 400.158 | Q6: =IF(AND(P6>0,Inputs!$C$6>0),P6/Inputs!$C$6*Inputs!$C$7,"") -> 9420.9731 | R6: =IF(C6="BC",'Rate Model'!$C$19,IF(C6="DBM",'Rate Model'!$E$19,"")) -> 3667.8247 | S6: =IF(AND(N6>0,R6>0),N6*R6,"") -> 1551489.9 | T6: =IF(A6<>"",Inputs!$C$47,"") -> 77 | U6: =IF(A6<>"",Inputs!$C$48,"") -> 95 | V6: 2 | W6: =IF(A6<>"",Inputs!$C$49,"") -> 32 | X6: 0 | Y6: =IF(AND(T6>0,U6>0,V6>0,W6>0),((T6*U6*V6)+X6)/W6,"") -> 457.1875 | Z6: =IF(AND(N6>0,Y6>0),N6*Y6,"") -> 193390.31 | AA6: =IF(A6<>"",Inputs!$C$57,"") -> 0.7 | AB6: =IF(AND(N6>0,AA6>0),N6*AA6,"") -> 296.1 | AC6: 0 | AD6: 1 | AE6: =IF(AND(J6>0,AC6>0),J6*AC6*Inputs!$C$71,0) -> 0 | AF6: =IF(AND(J6>0,AD6>0),J6*AD6*Inputs!$C$72,0) -> 50664 | AG6: =SUM(S6,Z6,AB6,AE6,AF6) -> 1795840.3 | AH6: =IF(AND(N6>0,AG6>0),AG6/N6,"") -> 4245.4853 | AI6: =IF(AND(I6>0,AG6>0),AG6/I6,"") -> 9976.8904 | AJ6: =IF(AND(J6>0,AG6>0),AG6/J6,"") -> 299.30671
I7: =IF(D7="GEOMETRY",IF(AND(E7>0,F7>0,G7>0),E7*F7*(G7/1000),""),IF(AND(H7>0,G7>0),H7,"")) | J7: =IF(AND(I7>0,G7>0),I7/(G7/1000),"") | K7: =IF(AND(J7>0,F7>0),J7/F7,"") | L7: =IF(C7="BC",'Mix Design'!$B$9,IF(C7="DBM",'Mix Design'!$C$9,"")) | M7: =IF(C7="BC",Inputs!$C$17,IF(C7="DBM",Inputs!$C$18,"")) | N7: =IF(AND(I7>0,M7>0),I7*M7,"") -> #VALUE! | O7: =IF(AND(N7>0,L7>0),N7*L7,"") -> #VALUE! | P7: =IF(AND(N7>0,O7>0),N7-O7,"") -> #VALUE! | Q7: =IF(AND(P7>0,Inputs!$C$6>0),P7/Inputs!$C$6*Inputs!$C$7,"") -> #VALUE! | R7: =IF(C7="BC",'Rate Model'!$C$19,IF(C7="DBM",'Rate Model'!$E$19,"")) | S7: =IF(AND(N7>0,R7>0),N7*R7,"") -> #VALUE! | T7: =IF(A7<>"",Inputs!$C$47,"") | U7: =IF(A7<>"",Inputs!$C$48,"") | V7: 2 | W7: =IF(A7<>"",Inputs!$C$49,"") | X7: 0 | Y7: =IF(AND(T7>0,U7>0,V7>0,W7>0),((T7*U7*V7)+X7)/W7,"") -> #VALUE! | Z7: =IF(AND(N7>0,Y7>0),N7*Y7,"") -> #VALUE! | AA7: =IF(A7<>"",Inputs!$C$57,"") | AB7: =IF(AND(N7>0,AA7>0),N7*AA7,"") -> #VALUE! | AE7: =IF(AND(J7>0,AC7>0),J7*AC7*Inputs!$C$71,0) -> 0 | AF7: =IF(AND(J7>0,AD7>0),J7*AD7*Inputs!$C$72,0) -> 0 | AG7: =SUM(S7,Z7,AB7,AE7,AF7) -> #VALUE! | AH7: =IF(AND(N7>0,AG7>0),AG7/N7,"") -> #VALUE! | AI7: =IF(AND(I7>0,AG7>0),AG7/I7,"") -> #VALUE! | AJ7: =IF(AND(J7>0,AG7>0),AG7/J7,"") -> #VALUE!
I8: =IF(D8="GEOMETRY",IF(AND(E8>0,F8>0,G8>0),E8*F8*(G8/1000),""),IF(AND(H8>0,G8>0),H8,"")) | J8: =IF(AND(I8>0,G8>0),I8/(G8/1000),"") | K8: =IF(AND(J8>0,F8>0),J8/F8,"") | L8: =IF(C8="BC",'Mix Design'!$B$9,IF(C8="DBM",'Mix Design'!$C$9,"")) | M8: =IF(C8="BC",Inputs!$C$17,IF(C8="DBM",Inputs!$C$18,"")) | N8: =IF(AND(I8>0,M8>0),I8*M8,"") -> #VALUE! | O8: =IF(AND(N8>0,L8>0),N8*L8,"") -> #VALUE! | P8: =IF(AND(N8>0,O8>0),N8-O8,"") -> #VALUE! | Q8: =IF(AND(P8>0,Inputs!$C$6>0),P8/Inputs!$C$6*Inputs!$C$7,"") -> #VALUE! | R8: =IF(C8="BC",'Rate Model'!$C$19,IF(C8="DBM",'Rate Model'!$E$19,"")) | S8: =IF(AND(N8>0,R8>0),N8*R8,"") -> #VALUE! | T8: =IF(A8<>"",Inputs!$C$47,"") | U8: =IF(A8<>"",Inputs!$C$48,"") | V8: 2 | W8: =IF(A8<>"",Inputs!$C$49,"") | X8: 0 | Y8: =IF(AND(T8>0,U8>0,V8>0,W8>0),((T8*U8*V8)+X8)/W8,"") -> #VALUE! | Z8: =IF(AND(N8>0,Y8>0),N8*Y8,"") -> #VALUE! | AA8: =IF(A8<>"",Inputs!$C$57,"") | AB8: =IF(AND(N8>0,AA8>0),N8*AA8,"") -> #VALUE! | AE8: =IF(AND(J8>0,AC8>0),J8*AC8*Inputs!$C$71,0) -> 0 | AF8: =IF(AND(J8>0,AD8>0),J8*AD8*Inputs!$C$72,0) -> 0 | AG8: =SUM(S8,Z8,AB8,AE8,AF8) -> #VALUE! | AH8: =IF(AND(N8>0,AG8>0),AG8/N8,"") -> #VALUE! | AI8: =IF(AND(I8>0,AG8>0),AG8/I8,"") -> #VALUE! | AJ8: =IF(AND(J8>0,AG8>0),AG8/J8,"") -> #VALUE!
I9: =IF(D9="GEOMETRY",IF(AND(E9>0,F9>0,G9>0),E9*F9*(G9/1000),""),IF(AND(H9>0,G9>0),H9,"")) | J9: =IF(AND(I9>0,G9>0),I9/(G9/1000),"") | K9: =IF(AND(J9>0,F9>0),J9/F9,"") | L9: =IF(C9="BC",'Mix Design'!$B$9,IF(C9="DBM",'Mix Design'!$C$9,"")) | M9: =IF(C9="BC",Inputs!$C$17,IF(C9="DBM",Inputs!$C$18,"")) | N9: =IF(AND(I9>0,M9>0),I9*M9,"") -> #VALUE! | O9: =IF(AND(N9>0,L9>0),N9*L9,"") -> #VALUE! | P9: =IF(AND(N9>0,O9>0),N9-O9,"") -> #VALUE! | Q9: =IF(AND(P9>0,Inputs!$C$6>0),P9/Inputs!$C$6*Inputs!$C$7,"") -> #VALUE! | R9: =IF(C9="BC",'Rate Model'!$C$19,IF(C9="DBM",'Rate Model'!$E$19,"")) | S9: =IF(AND(N9>0,R9>0),N9*R9,"") -> #VALUE! | T9: =IF(A9<>"",Inputs!$C$47,"") | U9: =IF(A9<>"",Inputs!$C$48,"") | V9: 2 | W9: =IF(A9<>"",Inputs!$C$49,"") | X9: 0 | Y9: =IF(AND(T9>0,U9>0,V9>0,W9>0),((T9*U9*V9)+X9)/W9,"") -> #VALUE! | Z9: =IF(AND(N9>0,Y9>0),N9*Y9,"") -> #VALUE! | AA9: =IF(A9<>"",Inputs!$C$57,"") | AB9: =IF(AND(N9>0,AA9>0),N9*AA9,"") -> #VALUE! | AE9: =IF(AND(J9>0,AC9>0),J9*AC9*Inputs!$C$71,0) -> 0 | AF9: =IF(AND(J9>0,AD9>0),J9*AD9*Inputs!$C$72,0) -> 0 | AG9: =SUM(S9,Z9,AB9,AE9,AF9) -> #VALUE! | AH9: =IF(AND(N9>0,AG9>0),AG9/N9,"") -> #VALUE! | AI9: =IF(AND(I9>0,AG9>0),AG9/I9,"") -> #VALUE! | AJ9: =IF(AND(J9>0,AG9>0),AG9/J9,"") -> #VALUE!
I10: =IF(D10="GEOMETRY",IF(AND(E10>0,F10>0,G10>0),E10*F10*(G10/1000),""),IF(AND(H10>0,G10>0),H10,"")) | J10: =IF(AND(I10>0,G10>0),I10/(G10/1000),"") | K10: =IF(AND(J10>0,F10>0),J10/F10,"") | L10: =IF(C10="BC",'Mix Design'!$B$9,IF(C10="DBM",'Mix Design'!$C$9,"")) | M10: =IF(C10="BC",Inputs!$C$17,IF(C10="DBM",Inputs!$C$18,"")) | N10: =IF(AND(I10>0,M10>0),I10*M10,"") -> #VALUE! | O10: =IF(AND(N10>0,L10>0),N10*L10,"") -> #VALUE! | P10: =IF(AND(N10>0,O10>0),N10-O10,"") -> #VALUE! | Q10: =IF(AND(P10>0,Inputs!$C$6>0),P10/Inputs!$C$6*Inputs!$C$7,"") -> #VALUE! | R10: =IF(C10="BC",'Rate Model'!$C$19,IF(C10="DBM",'Rate Model'!$E$19,"")) | S10: =IF(AND(N10>0,R10>0),N10*R10,"") -> #VALUE! | T10: =IF(A10<>"",Inputs!$C$47,"") | U10: =IF(A10<>"",Inputs!$C$48,"") | V10: 2 | W10: =IF(A10<>"",Inputs!$C$49,"") | X10: 0 | Y10: =IF(AND(T10>0,U10>0,V10>0,W10>0),((T10*U10*V10)+X10)/W10,"") -> #VALUE! | Z10: =IF(AND(N10>0,Y10>0),N10*Y10,"") -> #VALUE! | AA10: =IF(A10<>"",Inputs!$C$57,"") | AB10: =IF(AND(N10>0,AA10>0),N10*AA10,"") -> #VALUE! | AE10: =IF(AND(J10>0,AC10>0),J10*AC10*Inputs!$C$71,0) -> 0 | AF10: =IF(AND(J10>0,AD10>0),J10*AD10*Inputs!$C$72,0) -> 0 | AG10: =SUM(S10,Z10,AB10,AE10,AF10) -> #VALUE! | AH10: =IF(AND(N10>0,AG10>0),AG10/N10,"") -> #VALUE! | AI10: =IF(AND(I10>0,AG10>0),AG10/I10,"") -> #VALUE! | AJ10: =IF(AND(J10>0,AG10>0),AG10/J10,"") -> #VALUE!
I11: =IF(D11="GEOMETRY",IF(AND(E11>0,F11>0,G11>0),E11*F11*(G11/1000),""),IF(AND(H11>0,G11>0),H11,"")) | J11: =IF(AND(I11>0,G11>0),I11/(G11/1000),"") | K11: =IF(AND(J11>0,F11>0),J11/F11,"") | L11: =IF(C11="BC",'Mix Design'!$B$9,IF(C11="DBM",'Mix Design'!$C$9,"")) | M11: =IF(C11="BC",Inputs!$C$17,IF(C11="DBM",Inputs!$C$18,"")) | N11: =IF(AND(I11>0,M11>0),I11*M11,"") -> #VALUE! | O11: =IF(AND(N11>0,L11>0),N11*L11,"") -> #VALUE! | P11: =IF(AND(N11>0,O11>0),N11-O11,"") -> #VALUE! | Q11: =IF(AND(P11>0,Inputs!$C$6>0),P11/Inputs!$C$6*Inputs!$C$7,"") -> #VALUE! | R11: =IF(C11="BC",'Rate Model'!$C$19,IF(C11="DBM",'Rate Model'!$E$19,"")) | S11: =IF(AND(N11>0,R11>0),N11*R11,"") -> #VALUE! | T11: =IF(A11<>"",Inputs!$C$47,"") | U11: =IF(A11<>"",Inputs!$C$48,"") | V11: 2 | W11: =IF(A11<>"",Inputs!$C$49,"") | X11: 0 | Y11: =IF(AND(T11>0,U11>0,V11>0,W11>0),((T11*U11*V11)+X11)/W11,"") -> #VALUE! | Z11: =IF(AND(N11>0,Y11>0),N11*Y11,"") -> #VALUE! | AA11: =IF(A11<>"",Inputs!$C$57,"") | AB11: =IF(AND(N11>0,AA11>0),N11*AA11,"") -> #VALUE! | AE11: =IF(AND(J11>0,AC11>0),J11*AC11*Inputs!$C$71,0) -> 0 | AF11: =IF(AND(J11>0,AD11>0),J11*AD11*Inputs!$C$72,0) -> 0 | AG11: =SUM(S11,Z11,AB11,AE11,AF11) -> #VALUE! | AH11: =IF(AND(N11>0,AG11>0),AG11/N11,"") -> #VALUE! | AI11: =IF(AND(I11>0,AG11>0),AG11/I11,"") -> #VALUE! | AJ11: =IF(AND(J11>0,AG11>0),AG11/J11,"") -> #VALUE!
I12: =IF(D12="GEOMETRY",IF(AND(E12>0,F12>0,G12>0),E12*F12*(G12/1000),""),IF(AND(H12>0,G12>0),H12,"")) | J12: =IF(AND(I12>0,G12>0),I12/(G12/1000),"") | K12: =IF(AND(J12>0,F12>0),J12/F12,"") | L12: =IF(C12="BC",'Mix Design'!$B$9,IF(C12="DBM",'Mix Design'!$C$9,"")) | M12: =IF(C12="BC",Inputs!$C$17,IF(C12="DBM",Inputs!$C$18,"")) | N12: =IF(AND(I12>0,M12>0),I12*M12,"") -> #VALUE! | O12: =IF(AND(N12>0,L12>0),N12*L12,"") -> #VALUE! | P12: =IF(AND(N12>0,O12>0),N12-O12,"") -> #VALUE! | Q12: =IF(AND(P12>0,Inputs!$C$6>0),P12/Inputs!$C$6*Inputs!$C$7,"") -> #VALUE! | R12: =IF(C12="BC",'Rate Model'!$C$19,IF(C12="DBM",'Rate Model'!$E$19,"")) | S12: =IF(AND(N12>0,R12>0),N12*R12,"") -> #VALUE! | T12: =IF(A12<>"",Inputs!$C$47,"") | U12: =IF(A12<>"",Inputs!$C$48,"") | V12: 2 | W12: =IF(A12<>"",Inputs!$C$49,"") | X12: 0 | Y12: =IF(AND(T12>0,U12>0,V12>0,W12>0),((T12*U12*V12)+X12)/W12,"") -> #VALUE! | Z12: =IF(AND(N12>0,Y12>0),N12*Y12,"") -> #VALUE! | AA12: =IF(A12<>"",Inputs!$C$57,"") | AB12: =IF(AND(N12>0,AA12>0),N12*AA12,"") -> #VALUE! | AE12: =IF(AND(J12>0,AC12>0),J12*AC12*Inputs!$C$71,0) -> 0 | AF12: =IF(AND(J12>0,AD12>0),J12*AD12*Inputs!$C$72,0) -> 0 | AG12: =SUM(S12,Z12,AB12,AE12,AF12) -> #VALUE! | AH12: =IF(AND(N12>0,AG12>0),AG12/N12,"") -> #VALUE! | AI12: =IF(AND(I12>0,AG12>0),AG12/I12,"") -> #VALUE! | AJ12: =IF(AND(J12>0,AG12>0),AG12/J12,"") -> #VALUE!
I13: =IF(D13="GEOMETRY",IF(AND(E13>0,F13>0,G13>0),E13*F13*(G13/1000),""),IF(AND(H13>0,G13>0),H13,"")) | J13: =IF(AND(I13>0,G13>0),I13/(G13/1000),"") | K13: =IF(AND(J13>0,F13>0),J13/F13,"") | L13: =IF(C13="BC",'Mix Design'!$B$9,IF(C13="DBM",'Mix Design'!$C$9,"")) | M13: =IF(C13="BC",Inputs!$C$17,IF(C13="DBM",Inputs!$C$18,"")) | N13: =IF(AND(I13>0,M13>0),I13*M13,"") -> #VALUE! | O13: =IF(AND(N13>0,L13>0),N13*L13,"") -> #VALUE! | P13: =IF(AND(N13>0,O13>0),N13-O13,"") -> #VALUE! | Q13: =IF(AND(P13>0,Inputs!$C$6>0),P13/Inputs!$C$6*Inputs!$C$7,"") -> #VALUE! | R13: =IF(C13="BC",'Rate Model'!$C$19,IF(C13="DBM",'Rate Model'!$E$19,"")) | S13: =IF(AND(N13>0,R13>0),N13*R13,"") -> #VALUE! | T13: =IF(A13<>"",Inputs!$C$47,"") | U13: =IF(A13<>"",Inputs!$C$48,"") | V13: 2 | W13: =IF(A13<>"",Inputs!$C$49,"") | X13: 0 | Y13: =IF(AND(T13>0,U13>0,V13>0,W13>0),((T13*U13*V13)+X13)/W13,"") -> #VALUE! | Z13: =IF(AND(N13>0,Y13>0),N13*Y13,"") -> #VALUE! | AA13: =IF(A13<>"",Inputs!$C$57,"") | AB13: =IF(AND(N13>0,AA13>0),N13*AA13,"") -> #VALUE! | AE13: =IF(AND(J13>0,AC13>0),J13*AC13*Inputs!$C$71,0) -> 0 | AF13: =IF(AND(J13>0,AD13>0),J13*AD13*Inputs!$C$72,0) -> 0 | AG13: =SUM(S13,Z13,AB13,AE13,AF13) -> #VALUE! | AH13: =IF(AND(N13>0,AG13>0),AG13/N13,"") -> #VALUE! | AI13: =IF(AND(I13>0,AG13>0),AG13/I13,"") -> #VALUE! | AJ13: =IF(AND(J13>0,AG13>0),AG13/J13,"") -> #VALUE!
I14: =IF(D14="GEOMETRY",IF(AND(E14>0,F14>0,G14>0),E14*F14*(G14/1000),""),IF(AND(H14>0,G14>0),H14,"")) | J14: =IF(AND(I14>0,G14>0),I14/(G14/1000),"") | K14: =IF(AND(J14>0,F14>0),J14/F14,"") | L14: =IF(C14="BC",'Mix Design'!$B$9,IF(C14="DBM",'Mix Design'!$C$9,"")) | M14: =IF(C14="BC",Inputs!$C$17,IF(C14="DBM",Inputs!$C$18,"")) | N14: =IF(AND(I14>0,M14>0),I14*M14,"") -> #VALUE! | O14: =IF(AND(N14>0,L14>0),N14*L14,"") -> #VALUE! | P14: =IF(AND(N14>0,O14>0),N14-O14,"") -> #VALUE! | Q14: =IF(AND(P14>0,Inputs!$C$6>0),P14/Inputs!$C$6*Inputs!$C$7,"") -> #VALUE! | R14: =IF(C14="BC",'Rate Model'!$C$19,IF(C14="DBM",'Rate Model'!$E$19,"")) | S14: =IF(AND(N14>0,R14>0),N14*R14,"") -> #VALUE! | T14: =IF(A14<>"",Inputs!$C$47,"") | U14: =IF(A14<>"",Inputs!$C$48,"") | V14: 2 | W14: =IF(A14<>"",Inputs!$C$49,"") | X14: 0 | Y14: =IF(AND(T14>0,U14>0,V14>0,W14>0),((T14*U14*V14)+X14)/W14,"") -> #VALUE! | Z14: =IF(AND(N14>0,Y14>0),N14*Y14,"") -> #VALUE! | AA14: =IF(A14<>"",Inputs!$C$57,"") | AB14: =IF(AND(N14>0,AA14>0),N14*AA14,"") -> #VALUE! | AE14: =IF(AND(J14>0,AC14>0),J14*AC14*Inputs!$C$71,0) -> 0 | AF14: =IF(AND(J14>0,AD14>0),J14*AD14*Inputs!$C$72,0) -> 0 | AG14: =SUM(S14,Z14,AB14,AE14,AF14) -> #VALUE! | AH14: =IF(AND(N14>0,AG14>0),AG14/N14,"") -> #VALUE! | AI14: =IF(AND(I14>0,AG14>0),AG14/I14,"") -> #VALUE! | AJ14: =IF(AND(J14>0,AG14>0),AG14/J14,"") -> #VALUE!
I15: =IF(D15="GEOMETRY",IF(AND(E15>0,F15>0,G15>0),E15*F15*(G15/1000),""),IF(AND(H15>0,G15>0),H15,"")) | J15: =IF(AND(I15>0,G15>0),I15/(G15/1000),"") | K15: =IF(AND(J15>0,F15>0),J15/F15,"") | L15: =IF(C15="BC",'Mix Design'!$B$9,IF(C15="DBM",'Mix Design'!$C$9,"")) | M15: =IF(C15="BC",Inputs!$C$17,IF(C15="DBM",Inputs!$C$18,"")) | N15: =IF(AND(I15>0,M15>0),I15*M15,"") -> #VALUE! | O15: =IF(AND(N15>0,L15>0),N15*L15,"") -> #VALUE! | P15: =IF(AND(N15>0,O15>0),N15-O15,"") -> #VALUE! | Q15: =IF(AND(P15>0,Inputs!$C$6>0),P15/Inputs!$C$6*Inputs!$C$7,"") -> #VALUE! | R15: =IF(C15="BC",'Rate Model'!$C$19,IF(C15="DBM",'Rate Model'!$E$19,"")) | S15: =IF(AND(N15>0,R15>0),N15*R15,"") -> #VALUE! | T15: =IF(A15<>"",Inputs!$C$47,"") | U15: =IF(A15<>"",Inputs!$C$48,"") | V15: 2 | W15: =IF(A15<>"",Inputs!$C$49,"") | X15: 0 | Y15: =IF(AND(T15>0,U15>0,V15>0,W15>0),((T15*U15*V15)+X15)/W15,"") -> #VALUE! | Z15: =IF(AND(N15>0,Y15>0),N15*Y15,"") -> #VALUE! | AA15: =IF(A15<>"",Inputs!$C$57,"") | AB15: =IF(AND(N15>0,AA15>0),N15*AA15,"") -> #VALUE! | AE15: =IF(AND(J15>0,AC15>0),J15*AC15*Inputs!$C$71,0) -> 0 | AF15: =IF(AND(J15>0,AD15>0),J15*AD15*Inputs!$C$72,0) -> 0 | AG15: =SUM(S15,Z15,AB15,AE15,AF15) -> #VALUE! | AH15: =IF(AND(N15>0,AG15>0),AG15/N15,"") -> #VALUE! | AI15: =IF(AND(I15>0,AG15>0),AG15/I15,"") -> #VALUE! | AJ15: =IF(AND(J15>0,AG15>0),AG15/J15,"") -> #VALUE!
I16: =IF(D16="GEOMETRY",IF(AND(E16>0,F16>0,G16>0),E16*F16*(G16/1000),""),IF(AND(H16>0,G16>0),H16,"")) | J16: =IF(AND(I16>0,G16>0),I16/(G16/1000),"") | K16: =IF(AND(J16>0,F16>0),J16/F16,"") | L16: =IF(C16="BC",'Mix Design'!$B$9,IF(C16="DBM",'Mix Design'!$C$9,"")) | M16: =IF(C16="BC",Inputs!$C$17,IF(C16="DBM",Inputs!$C$18,"")) | N16: =IF(AND(I16>0,M16>0),I16*M16,"") -> #VALUE! | O16: =IF(AND(N16>0,L16>0),N16*L16,"") -> #VALUE! | P16: =IF(AND(N16>0,O16>0),N16-O16,"") -> #VALUE! | Q16: =IF(AND(P16>0,Inputs!$C$6>0),P16/Inputs!$C$6*Inputs!$C$7,"") -> #VALUE! | R16: =IF(C16="BC",'Rate Model'!$C$19,IF(C16="DBM",'Rate Model'!$E$19,"")) | S16: =IF(AND(N16>0,R16>0),N16*R16,"") -> #VALUE! | T16: =IF(A16<>"",Inputs!$C$47,"") | U16: =IF(A16<>"",Inputs!$C$48,"") | V16: 2 | W16: =IF(A16<>"",Inputs!$C$49,"") | X16: 0 | Y16: =IF(AND(T16>0,U16>0,V16>0,W16>0),((T16*U16*V16)+X16)/W16,"") -> #VALUE! | Z16: =IF(AND(N16>0,Y16>0),N16*Y16,"") -> #VALUE! | AA16: =IF(A16<>"",Inputs!$C$57,"") | AB16: =IF(AND(N16>0,AA16>0),N16*AA16,"") -> #VALUE! | AE16: =IF(AND(J16>0,AC16>0),J16*AC16*Inputs!$C$71,0) -> 0 | AF16: =IF(AND(J16>0,AD16>0),J16*AD16*Inputs!$C$72,0) -> 0 | AG16: =SUM(S16,Z16,AB16,AE16,AF16) -> #VALUE! | AH16: =IF(AND(N16>0,AG16>0),AG16/N16,"") -> #VALUE! | AI16: =IF(AND(I16>0,AG16>0),AG16/I16,"") -> #VALUE! | AJ16: =IF(AND(J16>0,AG16>0),AG16/J16,"") -> #VALUE!
I17: =IF(D17="GEOMETRY",IF(AND(E17>0,F17>0,G17>0),E17*F17*(G17/1000),""),IF(AND(H17>0,G17>0),H17,"")) | J17: =IF(AND(I17>0,G17>0),I17/(G17/1000),"") | K17: =IF(AND(J17>0,F17>0),J17/F17,"") | L17: =IF(C17="BC",'Mix Design'!$B$9,IF(C17="DBM",'Mix Design'!$C$9,"")) | M17: =IF(C17="BC",Inputs!$C$17,IF(C17="DBM",Inputs!$C$18,"")) | N17: =IF(AND(I17>0,M17>0),I17*M17,"") -> #VALUE! | O17: =IF(AND(N17>0,L17>0),N17*L17,"") -> #VALUE! | P17: =IF(AND(N17>0,O17>0),N17-O17,"") -> #VALUE! | Q17: =IF(AND(P17>0,Inputs!$C$6>0),P17/Inputs!$C$6*Inputs!$C$7,"") -> #VALUE! | R17: =IF(C17="BC",'Rate Model'!$C$19,IF(C17="DBM",'Rate Model'!$E$19,"")) | S17: =IF(AND(N17>0,R17>0),N17*R17,"") -> #VALUE! | T17: =IF(A17<>"",Inputs!$C$47,"") | U17: =IF(A17<>"",Inputs!$C$48,"") | V17: 2 | W17: =IF(A17<>"",Inputs!$C$49,"") | X17: 0 | Y17: =IF(AND(T17>0,U17>0,V17>0,W17>0),((T17*U17*V17)+X17)/W17,"") -> #VALUE! | Z17: =IF(AND(N17>0,Y17>0),N17*Y17,"") -> #VALUE! | AA17: =IF(A17<>"",Inputs!$C$57,"") | AB17: =IF(AND(N17>0,AA17>0),N17*AA17,"") -> #VALUE! | AE17: =IF(AND(J17>0,AC17>0),J17*AC17*Inputs!$C$71,0) -> 0 | AF17: =IF(AND(J17>0,AD17>0),J17*AD17*Inputs!$C$72,0) -> 0 | AG17: =SUM(S17,Z17,AB17,AE17,AF17) -> #VALUE! | AH17: =IF(AND(N17>0,AG17>0),AG17/N17,"") -> #VALUE! | AI17: =IF(AND(I17>0,AG17>0),AG17/I17,"") -> #VALUE! | AJ17: =IF(AND(J17>0,AG17>0),AG17/J17,"") -> #VALUE!
I18: =IF(D18="GEOMETRY",IF(AND(E18>0,F18>0,G18>0),E18*F18*(G18/1000),""),IF(AND(H18>0,G18>0),H18,"")) | J18: =IF(AND(I18>0,G18>0),I18/(G18/1000),"") | K18: =IF(AND(J18>0,F18>0),J18/F18,"") | L18: =IF(C18="BC",'Mix Design'!$B$9,IF(C18="DBM",'Mix Design'!$C$9,"")) | M18: =IF(C18="BC",Inputs!$C$17,IF(C18="DBM",Inputs!$C$18,"")) | N18: =IF(AND(I18>0,M18>0),I18*M18,"") -> #VALUE! | O18: =IF(AND(N18>0,L18>0),N18*L18,"") -> #VALUE! | P18: =IF(AND(N18>0,O18>0),N18-O18,"") -> #VALUE! | Q18: =IF(AND(P18>0,Inputs!$C$6>0),P18/Inputs!$C$6*Inputs!$C$7,"") -> #VALUE! | R18: =IF(C18="BC",'Rate Model'!$C$19,IF(C18="DBM",'Rate Model'!$E$19,"")) | S18: =IF(AND(N18>0,R18>0),N18*R18,"") -> #VALUE! | T18: =IF(A18<>"",Inputs!$C$47,"") | U18: =IF(A18<>"",Inputs!$C$48,"") | V18: 2 | W18: =IF(A18<>"",Inputs!$C$49,"") | X18: 0 | Y18: =IF(AND(T18>0,U18>0,V18>0,W18>0),((T18*U18*V18)+X18)/W18,"") -> #VALUE! | Z18: =IF(AND(N18>0,Y18>0),N18*Y18,"") -> #VALUE! | AA18: =IF(A18<>"",Inputs!$C$57,"") | AB18: =IF(AND(N18>0,AA18>0),N18*AA18,"") -> #VALUE! | AE18: =IF(AND(J18>0,AC18>0),J18*AC18*Inputs!$C$71,0) -> 0 | AF18: =IF(AND(J18>0,AD18>0),J18*AD18*Inputs!$C$72,0) -> 0 | AG18: =SUM(S18,Z18,AB18,AE18,AF18) -> #VALUE! | AH18: =IF(AND(N18>0,AG18>0),AG18/N18,"") -> #VALUE! | AI18: =IF(AND(I18>0,AG18>0),AG18/I18,"") -> #VALUE! | AJ18: =IF(AND(J18>0,AG18>0),AG18/J18,"") -> #VALUE!
... I203: =IF(D203="GEOMETRY",IF(AND(E203>0,F203>0,G203>0),E203*F203*(G203/1000),""),IF(AND(H203>0,G203>0),H203,"")) | J203: =IF(AND(I203>0,G203>0),I203/(G203/1000),"") | K203: =IF(AND(J203>0,F203>0),J203/F203,"") | L203: =IF(C203="BC",'Mix Design'!$B$9,IF(C203="DBM",'Mix Design'!$C$9,"")) | M203: =IF(C203="BC",Inputs!$C$17,IF(C203="DBM",Inputs!$C$18,"")) | N203: =IF(AND(I203>0,M203>0),I203*M203,"") -> #VALUE! | O203: =IF(AND(N203>0,L203>0),N203*L203,"") -> #VALUE! | P203: =IF(AND(N203>0,O203>0),N203-O203,"") -> #VALUE! | Q203: =IF(AND(P203>0,Inputs!$C$6>0),P203/Inputs!$C$6*Inputs!$C$7,"") -> #VALUE! | R203: =IF(C203="BC",'Rate Model'!$C$19,IF(C203="DBM",'Rate Model'!$E$19,"")) | S203: =IF(AND(N203>0,R203>0),N203*R203,"") -> #VALUE! | T203: =IF(A203<>"",Inputs!$C$47,"") | U203: =IF(A203<>"",Inputs!$C$48,"") | V203: 2 | W203: =IF(A203<>"",Inputs!$C$49,"") | X203: 0 | Y203: =IF(AND(T203>0,U203>0,V203>0,W203>0),((T203*U203*V203)+X203)/W203,"") -> #VALUE! | Z203: =IF(AND(N203>0,Y203>0),N203*Y203,"") -> #VALUE! | AA203: =IF(A203<>"",Inputs!$C$57,"") | AB203: =IF(AND(N203>0,AA203>0),N203*AA203,"") -> #VALUE! | AE203: =IF(AND(J203>0,AC203>0),J203*AC203*Inputs!$C$71,0) -> 0 | AF203: =IF(AND(J203>0,AD203>0),J203*AD203*Inputs!$C$72,0) -> 0 | AG203: =SUM(S203,Z203,AB203,AE203,AF203) -> #VALUE! | AH203: =IF(AND(N203>0,AG203>0),AG203/N203,"") -> #VALUE! | AI203: =IF(AND(I203>0,AG203>0),AG203/I203,"") -> #VALUE! | AJ203: =IF(AND(J203>0,AG203>0),AG203/J203,"") -> #VALUE!

Sheet Material Planner
A1: Material Planner
A2: Job-wise pull from Job Planner with component-wise quantities based on Mix Design. Use the summary block on the right for contractor/layer totals.
A3: Job ID | B3: Contractor | C3: Layer | D3: Qty Basis | E3: Length Used (m) | F3: Width (m) | G3: Thickness (mm) | H3: Final Qty (cum) | I3: Area (sqm) | J3: Mix Qty (MT) | K3: 20mm MT | L3: 10mm MT | M3: 6mm / chips MT | N3: Dust MT | O3: Filler MT | P3: Bitumen MT | Q3: Total Aggregates MT | R3: Aggregates CFT | S3: Plant Amount | T3: Transport Amount | U3: P&R Amount | V3: Prime Amount | W3: Tack Amount | X3: Total Amount | Z3: Contractor Summary
A4: ='Job Planner'!A4 -> J01 | B4: ='Job Planner'!B4 -> Murthy | C4: ='Job Planner'!C4 -> DBM | D4: ='Job Planner'!D4 -> BOQ_CUM | E4: =IF('Job Planner'!D4="GEOMETRY",'Job Planner'!E4,'Job Planner'!K4) -> 210 | F4: ='Job Planner'!F4 -> 5.5 | G4: ='Job Planner'!G4 -> 50 | H4: ='Job Planner'!I4 -> 57.75 | I4: ='Job Planner'!J4 -> 1155 | J4: ='Job Planner'!N4 -> 132.825 | K4: =IF(C4="BC",J4*'Mix Design'!$B$4,IF(C4="DBM",J4*'Mix Design'!$C$4,"")) -> 26.565 | L4: =IF(C4="BC",J4*'Mix Design'!$B$5,IF(C4="DBM",J4*'Mix Design'!$C$5,"")) -> 33.20625 | M4: =IF(C4="BC",J4*'Mix Design'!$B$6,IF(C4="DBM",J4*'Mix Design'!$C$6,"")) -> 13.2825 | N4: =IF(C4="BC",J4*'Mix Design'!$B$7,IF(C4="DBM",J4*'Mix Design'!$C$7,"")) -> 55.388025 | O4: =IF(C4="BC",J4*'Mix Design'!$B$8,IF(C4="DBM",J4*'Mix Design'!$C$8,"")) -> 0 | P4: =IF(C4="BC",J4*'Mix Design'!$B$9,IF(C4="DBM",J4*'Mix Design'!$C$9,"")) -> 4.383225 | Q4: ='Job Planner'!P4 -> 128.44177 | R4: ='Job Planner'!Q4 -> 3023.9218 | S4: ='Job Planner'!S4 -> 346210.32 | T4: ='Job Planner'!Z4 -> 60725.93 | U4: ='Job Planner'!AB4 -> 92.9775 | V4: ='Job Planner'!AE4 -> 36613.5 | W4: ='Job Planner'!AF4 -> 0 | X4: ='Job Planner'!AG4 -> 443642.73 | Z4: Contractor | AA4: Layer | AB4: Mix Qty MT | AC4: Bitumen MT | AD4: Aggregates MT | AE4: Aggregates CFT | AF4: Total Amount
A5: ='Job Planner'!A5 -> J02 | B5: ='Job Planner'!B5 -> Murthy | C5: ='Job Planner'!C5 -> BC | D5: ='Job Planner'!D5 -> GEOMETRY | E5: =IF('Job Planner'!D5="GEOMETRY",'Job Planner'!E5,'Job Planner'!K5) -> 1100 | F5: ='Job Planner'!F5 -> 5.5 | G5: ='Job Planner'!G5 -> 30 | H5: ='Job Planner'!I5 -> 181.5 | I5: ='Job Planner'!J5 -> 6050 | J5: ='Job Planner'!N5 -> 426.525 | K5: =IF(C5="BC",J5*'Mix Design'!$B$4,IF(C5="DBM",J5*'Mix Design'!$C$4,"")) -> 0 | L5: =IF(C5="BC",J5*'Mix Design'!$B$5,IF(C5="DBM",J5*'Mix Design'!$C$5,"")) -> 74.21535 | M5: =IF(C5="BC",J5*'Mix Design'!$B$6,IF(C5="DBM",J5*'Mix Design'!$C$6,"")) -> 106.63125 | N5: =IF(C5="BC",J5*'Mix Design'!$B$7,IF(C5="DBM",J5*'Mix Design'!$C$7,"")) -> 222.64605 | O5: =IF(C5="BC",J5*'Mix Design'!$B$8,IF(C5="DBM",J5*'Mix Design'!$C$8,"")) -> 0 | P5: =IF(C5="BC",J5*'Mix Design'!$B$9,IF(C5="DBM",J5*'Mix Design'!$C$9,"")) -> 23.03235 | Q5: ='Job Planner'!P5 -> 403.49265 | R5: ='Job Planner'!Q5 -> 9499.4813 | S5: ='Job Planner'!S5 -> 1564418.9 | T5: ='Job Planner'!Z5 -> 195001.9 | U5: ='Job Planner'!AB5 -> 298.5675 | V5: ='Job Planner'!AE5 -> 0 | W5: ='Job Planner'!AF5 -> 51086.2 | X5: ='Job Planner'!AG5 -> 1810805.6 | AB5: =IF(OR(Z5="",AA5=""),"",SUMIFS($J$4:$J$203,$B$4:$B$203,Z5,$C$4:$C$203,AA5)) | AC5: =IF(OR(Z5="",AA5=""),"",SUMIFS($P$4:$P$203,$B$4:$B$203,Z5,$C$4:$C$203,AA5)) | AD5: =IF(OR(Z5="",AA5=""),"",SUMIFS($Q$4:$Q$203,$B$4:$B$203,Z5,$C$4:$C$203,AA5)) | AE5: =IF(OR(Z5="",AA5=""),"",SUMIFS($R$4:$R$203,$B$4:$B$203,Z5,$C$4:$C$203,AA5)) | AF5: =IF(OR(Z5="",AA5=""),"",SUMIFS($X$4:$X$203,$B$4:$B$203,Z5,$C$4:$C$203,AA5))
A6: ='Job Planner'!A6 -> J03 | B6: ='Job Planner'!B6 -> Approach Contractor | C6: ='Job Planner'!C6 -> BC | D6: ='Job Planner'!D6 -> BOQ_CUM | E6: =IF('Job Planner'!D6="GEOMETRY",'Job Planner'!E6,'Job Planner'!K6) -> 1090.9091 | F6: ='Job Planner'!F6 -> 5.5 | G6: ='Job Planner'!G6 -> 30 | H6: ='Job Planner'!I6 -> 180 | I6: ='Job Planner'!J6 -> 6000 | J6: ='Job Planner'!N6 -> 423 | K6: =IF(C6="BC",J6*'Mix Design'!$B$4,IF(C6="DBM",J6*'Mix Design'!$C$4,"")) -> 0 | L6: =IF(C6="BC",J6*'Mix Design'!$B$5,IF(C6="DBM",J6*'Mix Design'!$C$5,"")) -> 73.602 | M6: =IF(C6="BC",J6*'Mix Design'!$B$6,IF(C6="DBM",J6*'Mix Design'!$C$6,"")) -> 105.75 | N6: =IF(C6="BC",J6*'Mix Design'!$B$7,IF(C6="DBM",J6*'Mix Design'!$C$7,"")) -> 220.806 | O6: =IF(C6="BC",J6*'Mix Design'!$B$8,IF(C6="DBM",J6*'Mix Design'!$C$8,"")) -> 0 | P6: =IF(C6="BC",J6*'Mix Design'!$B$9,IF(C6="DBM",J6*'Mix Design'!$C$9,"")) -> 22.842 | Q6: ='Job Planner'!P6 -> 400.158 | R6: ='Job Planner'!Q6 -> 9420.9731 | S6: ='Job Planner'!S6 -> 1551489.9 | T6: ='Job Planner'!Z6 -> 193390.31 | U6: ='Job Planner'!AB6 -> 296.1 | V6: ='Job Planner'!AE6 -> 0 | W6: ='Job Planner'!AF6 -> 50664 | X6: ='Job Planner'!AG6 -> 1795840.3 | AB6: =IF(OR(Z6="",AA6=""),"",SUMIFS($J$4:$J$203,$B$4:$B$203,Z6,$C$4:$C$203,AA6)) | AC6: =IF(OR(Z6="",AA6=""),"",SUMIFS($P$4:$P$203,$B$4:$B$203,Z6,$C$4:$C$203,AA6)) | AD6: =IF(OR(Z6="",AA6=""),"",SUMIFS($Q$4:$Q$203,$B$4:$B$203,Z6,$C$4:$C$203,AA6)) | AE6: =IF(OR(Z6="",AA6=""),"",SUMIFS($R$4:$R$203,$B$4:$B$203,Z6,$C$4:$C$203,AA6)) | AF6: =IF(OR(Z6="",AA6=""),"",SUMIFS($X$4:$X$203,$B$4:$B$203,Z6,$C$4:$C$203,AA6))
A7: ='Job Planner'!A7 -> 0 | B7: ='Job Planner'!B7 -> 0 | C7: ='Job Planner'!C7 -> 0 | D7: ='Job Planner'!D7 -> 0 | E7: =IF('Job Planner'!D7="GEOMETRY",'Job Planner'!E7,'Job Planner'!K7) | F7: ='Job Planner'!F7 -> 0 | G7: ='Job Planner'!G7 -> 0 | H7: ='Job Planner'!I7 | I7: ='Job Planner'!J7 | J7: ='Job Planner'!N7 -> #VALUE! | K7: =IF(C7="BC",J7*'Mix Design'!$B$4,IF(C7="DBM",J7*'Mix Design'!$C$4,"")) | L7: =IF(C7="BC",J7*'Mix Design'!$B$5,IF(C7="DBM",J7*'Mix Design'!$C$5,"")) | M7: =IF(C7="BC",J7*'Mix Design'!$B$6,IF(C7="DBM",J7*'Mix Design'!$C$6,"")) | N7: =IF(C7="BC",J7*'Mix Design'!$B$7,IF(C7="DBM",J7*'Mix Design'!$C$7,"")) | O7: =IF(C7="BC",J7*'Mix Design'!$B$8,IF(C7="DBM",J7*'Mix Design'!$C$8,"")) | P7: =IF(C7="BC",J7*'Mix Design'!$B$9,IF(C7="DBM",J7*'Mix Design'!$C$9,"")) | Q7: ='Job Planner'!P7 -> #VALUE! | R7: ='Job Planner'!Q7 -> #VALUE! | S7: ='Job Planner'!S7 -> #VALUE! | T7: ='Job Planner'!Z7 -> #VALUE! | U7: ='Job Planner'!AB7 -> #VALUE! | V7: ='Job Planner'!AE7 -> 0 | W7: ='Job Planner'!AF7 -> 0 | X7: ='Job Planner'!AG7 -> #VALUE! | AB7: =IF(OR(Z7="",AA7=""),"",SUMIFS($J$4:$J$203,$B$4:$B$203,Z7,$C$4:$C$203,AA7)) | AC7: =IF(OR(Z7="",AA7=""),"",SUMIFS($P$4:$P$203,$B$4:$B$203,Z7,$C$4:$C$203,AA7)) | AD7: =IF(OR(Z7="",AA7=""),"",SUMIFS($Q$4:$Q$203,$B$4:$B$203,Z7,$C$4:$C$203,AA7)) | AE7: =IF(OR(Z7="",AA7=""),"",SUMIFS($R$4:$R$203,$B$4:$B$203,Z7,$C$4:$C$203,AA7)) | AF7: =IF(OR(Z7="",AA7=""),"",SUMIFS($X$4:$X$203,$B$4:$B$203,Z7,$C$4:$C$203,AA7))
A8: ='Job Planner'!A8 -> 0 | B8: ='Job Planner'!B8 -> 0 | C8: ='Job Planner'!C8 -> 0 | D8: ='Job Planner'!D8 -> 0 | E8: =IF('Job Planner'!D8="GEOMETRY",'Job Planner'!E8,'Job Planner'!K8) | F8: ='Job Planner'!F8 -> 0 | G8: ='Job Planner'!G8 -> 0 | H8: ='Job Planner'!I8 | I8: ='Job Planner'!J8 | J8: ='Job Planner'!N8 -> #VALUE! | K8: =IF(C8="BC",J8*'Mix Design'!$B$4,IF(C8="DBM",J8*'Mix Design'!$C$4,"")) | L8: =IF(C8="BC",J8*'Mix Design'!$B$5,IF(C8="DBM",J8*'Mix Design'!$C$5,"")) | M8: =IF(C8="BC",J8*'Mix Design'!$B$6,IF(C8="DBM",J8*'Mix Design'!$C$6,"")) | N8: =IF(C8="BC",J8*'Mix Design'!$B$7,IF(C8="DBM",J8*'Mix Design'!$C$7,"")) | O8: =IF(C8="BC",J8*'Mix Design'!$B$8,IF(C8="DBM",J8*'Mix Design'!$C$8,"")) | P8: =IF(C8="BC",J8*'Mix Design'!$B$9,IF(C8="DBM",J8*'Mix Design'!$C$9,"")) | Q8: ='Job Planner'!P8 -> #VALUE! | R8: ='Job Planner'!Q8 -> #VALUE! | S8: ='Job Planner'!S8 -> #VALUE! | T8: ='Job Planner'!Z8 -> #VALUE! | U8: ='Job Planner'!AB8 -> #VALUE! | V8: ='Job Planner'!AE8 -> 0 | W8: ='Job Planner'!AF8 -> 0 | X8: ='Job Planner'!AG8 -> #VALUE! | AB8: =IF(OR(Z8="",AA8=""),"",SUMIFS($J$4:$J$203,$B$4:$B$203,Z8,$C$4:$C$203,AA8)) | AC8: =IF(OR(Z8="",AA8=""),"",SUMIFS($P$4:$P$203,$B$4:$B$203,Z8,$C$4:$C$203,AA8)) | AD8: =IF(OR(Z8="",AA8=""),"",SUMIFS($Q$4:$Q$203,$B$4:$B$203,Z8,$C$4:$C$203,AA8)) | AE8: =IF(OR(Z8="",AA8=""),"",SUMIFS($R$4:$R$203,$B$4:$B$203,Z8,$C$4:$C$203,AA8)) | AF8: =IF(OR(Z8="",AA8=""),"",SUMIFS($X$4:$X$203,$B$4:$B$203,Z8,$C$4:$C$203,AA8))
A9: ='Job Planner'!A9 -> 0 | B9: ='Job Planner'!B9 -> 0 | C9: ='Job Planner'!C9 -> 0 | D9: ='Job Planner'!D9 -> 0 | E9: =IF('Job Planner'!D9="GEOMETRY",'Job Planner'!E9,'Job Planner'!K9) | F9: ='Job Planner'!F9 -> 0 | G9: ='Job Planner'!G9 -> 0 | H9: ='Job Planner'!I9 | I9: ='Job Planner'!J9 | J9: ='Job Planner'!N9 -> #VALUE! | K9: =IF(C9="BC",J9*'Mix Design'!$B$4,IF(C9="DBM",J9*'Mix Design'!$C$4,"")) | L9: =IF(C9="BC",J9*'Mix Design'!$B$5,IF(C9="DBM",J9*'Mix Design'!$C$5,"")) | M9: =IF(C9="BC",J9*'Mix Design'!$B$6,IF(C9="DBM",J9*'Mix Design'!$C$6,"")) | N9: =IF(C9="BC",J9*'Mix Design'!$B$7,IF(C9="DBM",J9*'Mix Design'!$C$7,"")) | O9: =IF(C9="BC",J9*'Mix Design'!$B$8,IF(C9="DBM",J9*'Mix Design'!$C$8,"")) | P9: =IF(C9="BC",J9*'Mix Design'!$B$9,IF(C9="DBM",J9*'Mix Design'!$C$9,"")) | Q9: ='Job Planner'!P9 -> #VALUE! | R9: ='Job Planner'!Q9 -> #VALUE! | S9: ='Job Planner'!S9 -> #VALUE! | T9: ='Job Planner'!Z9 -> #VALUE! | U9: ='Job Planner'!AB9 -> #VALUE! | V9: ='Job Planner'!AE9 -> 0 | W9: ='Job Planner'!AF9 -> 0 | X9: ='Job Planner'!AG9 -> #VALUE! | AB9: =IF(OR(Z9="",AA9=""),"",SUMIFS($J$4:$J$203,$B$4:$B$203,Z9,$C$4:$C$203,AA9)) | AC9: =IF(OR(Z9="",AA9=""),"",SUMIFS($P$4:$P$203,$B$4:$B$203,Z9,$C$4:$C$203,AA9)) | AD9: =IF(OR(Z9="",AA9=""),"",SUMIFS($Q$4:$Q$203,$B$4:$B$203,Z9,$C$4:$C$203,AA9)) | AE9: =IF(OR(Z9="",AA9=""),"",SUMIFS($R$4:$R$203,$B$4:$B$203,Z9,$C$4:$C$203,AA9)) | AF9: =IF(OR(Z9="",AA9=""),"",SUMIFS($X$4:$X$203,$B$4:$B$203,Z9,$C$4:$C$203,AA9))
A10: ='Job Planner'!A10 -> 0 | B10: ='Job Planner'!B10 -> 0 | C10: ='Job Planner'!C10 -> 0 | D10: ='Job Planner'!D10 -> 0 | E10: =IF('Job Planner'!D10="GEOMETRY",'Job Planner'!E10,'Job Planner'!K10) | F10: ='Job Planner'!F10 -> 0 | G10: ='Job Planner'!G10 -> 0 | H10: ='Job Planner'!I10 | I10: ='Job Planner'!J10 | J10: ='Job Planner'!N10 -> #VALUE! | K10: =IF(C10="BC",J10*'Mix Design'!$B$4,IF(C10="DBM",J10*'Mix Design'!$C$4,"")) | L10: =IF(C10="BC",J10*'Mix Design'!$B$5,IF(C10="DBM",J10*'Mix Design'!$C$5,"")) | M10: =IF(C10="BC",J10*'Mix Design'!$B$6,IF(C10="DBM",J10*'Mix Design'!$C$6,"")) | N10: =IF(C10="BC",J10*'Mix Design'!$B$7,IF(C10="DBM",J10*'Mix Design'!$C$7,"")) | O10: =IF(C10="BC",J10*'Mix Design'!$B$8,IF(C10="DBM",J10*'Mix Design'!$C$8,"")) | P10: =IF(C10="BC",J10*'Mix Design'!$B$9,IF(C10="DBM",J10*'Mix Design'!$C$9,"")) | Q10: ='Job Planner'!P10 -> #VALUE! | R10: ='Job Planner'!Q10 -> #VALUE! | S10: ='Job Planner'!S10 -> #VALUE! | T10: ='Job Planner'!Z10 -> #VALUE! | U10: ='Job Planner'!AB10 -> #VALUE! | V10: ='Job Planner'!AE10 -> 0 | W10: ='Job Planner'!AF10 -> 0 | X10: ='Job Planner'!AG10 -> #VALUE! | AB10: =IF(OR(Z10="",AA10=""),"",SUMIFS($J$4:$J$203,$B$4:$B$203,Z10,$C$4:$C$203,AA10)) | AC10: =IF(OR(Z10="",AA10=""),"",SUMIFS($P$4:$P$203,$B$4:$B$203,Z10,$C$4:$C$203,AA10)) | AD10: =IF(OR(Z10="",AA10=""),"",SUMIFS($Q$4:$Q$203,$B$4:$B$203,Z10,$C$4:$C$203,AA10)) | AE10: =IF(OR(Z10="",AA10=""),"",SUMIFS($R$4:$R$203,$B$4:$B$203,Z10,$C$4:$C$203,AA10)) | AF10: =IF(OR(Z10="",AA10=""),"",SUMIFS($X$4:$X$203,$B$4:$B$203,Z10,$C$4:$C$203,AA10))
A11: ='Job Planner'!A11 -> 0 | B11: ='Job Planner'!B11 -> 0 | C11: ='Job Planner'!C11 -> 0 | D11: ='Job Planner'!D11 -> 0 | E11: =IF('Job Planner'!D11="GEOMETRY",'Job Planner'!E11,'Job Planner'!K11) | F11: ='Job Planner'!F11 -> 0 | G11: ='Job Planner'!G11 -> 0 | H11: ='Job Planner'!I11 | I11: ='Job Planner'!J11 | J11: ='Job Planner'!N11 -> #VALUE! | K11: =IF(C11="BC",J11*'Mix Design'!$B$4,IF(C11="DBM",J11*'Mix Design'!$C$4,"")) | L11: =IF(C11="BC",J11*'Mix Design'!$B$5,IF(C11="DBM",J11*'Mix Design'!$C$5,"")) | M11: =IF(C11="BC",J11*'Mix Design'!$B$6,IF(C11="DBM",J11*'Mix Design'!$C$6,"")) | N11: =IF(C11="BC",J11*'Mix Design'!$B$7,IF(C11="DBM",J11*'Mix Design'!$C$7,"")) | O11: =IF(C11="BC",J11*'Mix Design'!$B$8,IF(C11="DBM",J11*'Mix Design'!$C$8,"")) | P11: =IF(C11="BC",J11*'Mix Design'!$B$9,IF(C11="DBM",J11*'Mix Design'!$C$9,"")) | Q11: ='Job Planner'!P11 -> #VALUE! | R11: ='Job Planner'!Q11 -> #VALUE! | S11: ='Job Planner'!S11 -> #VALUE! | T11: ='Job Planner'!Z11 -> #VALUE! | U11: ='Job Planner'!AB11 -> #VALUE! | V11: ='Job Planner'!AE11 -> 0 | W11: ='Job Planner'!AF11 -> 0 | X11: ='Job Planner'!AG11 -> #VALUE! | AB11: =IF(OR(Z11="",AA11=""),"",SUMIFS($J$4:$J$203,$B$4:$B$203,Z11,$C$4:$C$203,AA11)) | AC11: =IF(OR(Z11="",AA11=""),"",SUMIFS($P$4:$P$203,$B$4:$B$203,Z11,$C$4:$C$203,AA11)) | AD11: =IF(OR(Z11="",AA11=""),"",SUMIFS($Q$4:$Q$203,$B$4:$B$203,Z11,$C$4:$C$203,AA11)) | AE11: =IF(OR(Z11="",AA11=""),"",SUMIFS($R$4:$R$203,$B$4:$B$203,Z11,$C$4:$C$203,AA11)) | AF11: =IF(OR(Z11="",AA11=""),"",SUMIFS($X$4:$X$203,$B$4:$B$203,Z11,$C$4:$C$203,AA11))
A12: ='Job Planner'!A12 -> 0 | B12: ='Job Planner'!B12 -> 0 | C12: ='Job Planner'!C12 -> 0 | D12: ='Job Planner'!D12 -> 0 | E12: =IF('Job Planner'!D12="GEOMETRY",'Job Planner'!E12,'Job Planner'!K12) | F12: ='Job Planner'!F12 -> 0 | G12: ='Job Planner'!G12 -> 0 | H12: ='Job Planner'!I12 | I12: ='Job Planner'!J12 | J12: ='Job Planner'!N12 -> #VALUE! | K12: =IF(C12="BC",J12*'Mix Design'!$B$4,IF(C12="DBM",J12*'Mix Design'!$C$4,"")) | L12: =IF(C12="BC",J12*'Mix Design'!$B$5,IF(C12="DBM",J12*'Mix Design'!$C$5,"")) | M12: =IF(C12="BC",J12*'Mix Design'!$B$6,IF(C12="DBM",J12*'Mix Design'!$C$6,"")) | N12: =IF(C12="BC",J12*'Mix Design'!$B$7,IF(C12="DBM",J12*'Mix Design'!$C$7,"")) | O12: =IF(C12="BC",J12*'Mix Design'!$B$8,IF(C12="DBM",J12*'Mix Design'!$C$8,"")) | P12: =IF(C12="BC",J12*'Mix Design'!$B$9,IF(C12="DBM",J12*'Mix Design'!$C$9,"")) | Q12: ='Job Planner'!P12 -> #VALUE! | R12: ='Job Planner'!Q12 -> #VALUE! | S12: ='Job Planner'!S12 -> #VALUE! | T12: ='Job Planner'!Z12 -> #VALUE! | U12: ='Job Planner'!AB12 -> #VALUE! | V12: ='Job Planner'!AE12 -> 0 | W12: ='Job Planner'!AF12 -> 0 | X12: ='Job Planner'!AG12 -> #VALUE! | AB12: =IF(OR(Z12="",AA12=""),"",SUMIFS($J$4:$J$203,$B$4:$B$203,Z12,$C$4:$C$203,AA12)) | AC12: =IF(OR(Z12="",AA12=""),"",SUMIFS($P$4:$P$203,$B$4:$B$203,Z12,$C$4:$C$203,AA12)) | AD12: =IF(OR(Z12="",AA12=""),"",SUMIFS($Q$4:$Q$203,$B$4:$B$203,Z12,$C$4:$C$203,AA12)) | AE12: =IF(OR(Z12="",AA12=""),"",SUMIFS($R$4:$R$203,$B$4:$B$203,Z12,$C$4:$C$203,AA12)) | AF12: =IF(OR(Z12="",AA12=""),"",SUMIFS($X$4:$X$203,$B$4:$B$203,Z12,$C$4:$C$203,AA12))
A13: ='Job Planner'!A13 -> 0 | B13: ='Job Planner'!B13 -> 0 | C13: ='Job Planner'!C13 -> 0 | D13: ='Job Planner'!D13 -> 0 | E13: =IF('Job Planner'!D13="GEOMETRY",'Job Planner'!E13,'Job Planner'!K13) | F13: ='Job Planner'!F13 -> 0 | G13: ='Job Planner'!G13 -> 0 | H13: ='Job Planner'!I13 | I13: ='Job Planner'!J13 | J13: ='Job Planner'!N13 -> #VALUE! | K13: =IF(C13="BC",J13*'Mix Design'!$B$4,IF(C13="DBM",J13*'Mix Design'!$C$4,"")) | L13: =IF(C13="BC",J13*'Mix Design'!$B$5,IF(C13="DBM",J13*'Mix Design'!$C$5,"")) | M13: =IF(C13="BC",J13*'Mix Design'!$B$6,IF(C13="DBM",J13*'Mix Design'!$C$6,"")) | N13: =IF(C13="BC",J13*'Mix Design'!$B$7,IF(C13="DBM",J13*'Mix Design'!$C$7,"")) | O13: =IF(C13="BC",J13*'Mix Design'!$B$8,IF(C13="DBM",J13*'Mix Design'!$C$8,"")) | P13: =IF(C13="BC",J13*'Mix Design'!$B$9,IF(C13="DBM",J13*'Mix Design'!$C$9,"")) | Q13: ='Job Planner'!P13 -> #VALUE! | R13: ='Job Planner'!Q13 -> #VALUE! | S13: ='Job Planner'!S13 -> #VALUE! | T13: ='Job Planner'!Z13 -> #VALUE! | U13: ='Job Planner'!AB13 -> #VALUE! | V13: ='Job Planner'!AE13 -> 0 | W13: ='Job Planner'!AF13 -> 0 | X13: ='Job Planner'!AG13 -> #VALUE! | AB13: =IF(OR(Z13="",AA13=""),"",SUMIFS($J$4:$J$203,$B$4:$B$203,Z13,$C$4:$C$203,AA13)) | AC13: =IF(OR(Z13="",AA13=""),"",SUMIFS($P$4:$P$203,$B$4:$B$203,Z13,$C$4:$C$203,AA13)) | AD13: =IF(OR(Z13="",AA13=""),"",SUMIFS($Q$4:$Q$203,$B$4:$B$203,Z13,$C$4:$C$203,AA13)) | AE13: =IF(OR(Z13="",AA13=""),"",SUMIFS($R$4:$R$203,$B$4:$B$203,Z13,$C$4:$C$203,AA13)) | AF13: =IF(OR(Z13="",AA13=""),"",SUMIFS($X$4:$X$203,$B$4:$B$203,Z13,$C$4:$C$203,AA13))
A14: ='Job Planner'!A14 -> 0 | B14: ='Job Planner'!B14 -> 0 | C14: ='Job Planner'!C14 -> 0 | D14: ='Job Planner'!D14 -> 0 | E14: =IF('Job Planner'!D14="GEOMETRY",'Job Planner'!E14,'Job Planner'!K14) | F14: ='Job Planner'!F14 -> 0 | G14: ='Job Planner'!G14 -> 0 | H14: ='Job Planner'!I14 | I14: ='Job Planner'!J14 | J14: ='Job Planner'!N14 -> #VALUE! | K14: =IF(C14="BC",J14*'Mix Design'!$B$4,IF(C14="DBM",J14*'Mix Design'!$C$4,"")) | L14: =IF(C14="BC",J14*'Mix Design'!$B$5,IF(C14="DBM",J14*'Mix Design'!$C$5,"")) | M14: =IF(C14="BC",J14*'Mix Design'!$B$6,IF(C14="DBM",J14*'Mix Design'!$C$6,"")) | N14: =IF(C14="BC",J14*'Mix Design'!$B$7,IF(C14="DBM",J14*'Mix Design'!$C$7,"")) | O14: =IF(C14="BC",J14*'Mix Design'!$B$8,IF(C14="DBM",J14*'Mix Design'!$C$8,"")) | P14: =IF(C14="BC",J14*'Mix Design'!$B$9,IF(C14="DBM",J14*'Mix Design'!$C$9,"")) | Q14: ='Job Planner'!P14 -> #VALUE! | R14: ='Job Planner'!Q14 -> #VALUE! | S14: ='Job Planner'!S14 -> #VALUE! | T14: ='Job Planner'!Z14 -> #VALUE! | U14: ='Job Planner'!AB14 -> #VALUE! | V14: ='Job Planner'!AE14 -> 0 | W14: ='Job Planner'!AF14 -> 0 | X14: ='Job Planner'!AG14 -> #VALUE! | AB14: =IF(OR(Z14="",AA14=""),"",SUMIFS($J$4:$J$203,$B$4:$B$203,Z14,$C$4:$C$203,AA14)) | AC14: =IF(OR(Z14="",AA14=""),"",SUMIFS($P$4:$P$203,$B$4:$B$203,Z14,$C$4:$C$203,AA14)) | AD14: =IF(OR(Z14="",AA14=""),"",SUMIFS($Q$4:$Q$203,$B$4:$B$203,Z14,$C$4:$C$203,AA14)) | AE14: =IF(OR(Z14="",AA14=""),"",SUMIFS($R$4:$R$203,$B$4:$B$203,Z14,$C$4:$C$203,AA14)) | AF14: =IF(OR(Z14="",AA14=""),"",SUMIFS($X$4:$X$203,$B$4:$B$203,Z14,$C$4:$C$203,AA14))
A15: ='Job Planner'!A15 -> 0 | B15: ='Job Planner'!B15 -> 0 | C15: ='Job Planner'!C15 -> 0 | D15: ='Job Planner'!D15 -> 0 | E15: =IF('Job Planner'!D15="GEOMETRY",'Job Planner'!E15,'Job Planner'!K15) | F15: ='Job Planner'!F15 -> 0 | G15: ='Job Planner'!G15 -> 0 | H15: ='Job Planner'!I15 | I15: ='Job Planner'!J15 | J15: ='Job Planner'!N15 -> #VALUE! | K15: =IF(C15="BC",J15*'Mix Design'!$B$4,IF(C15="DBM",J15*'Mix Design'!$C$4,"")) | L15: =IF(C15="BC",J15*'Mix Design'!$B$5,IF(C15="DBM",J15*'Mix Design'!$C$5,"")) | M15: =IF(C15="BC",J15*'Mix Design'!$B$6,IF(C15="DBM",J15*'Mix Design'!$C$6,"")) | N15: =IF(C15="BC",J15*'Mix Design'!$B$7,IF(C15="DBM",J15*'Mix Design'!$C$7,"")) | O15: =IF(C15="BC",J15*'Mix Design'!$B$8,IF(C15="DBM",J15*'Mix Design'!$C$8,"")) | P15: =IF(C15="BC",J15*'Mix Design'!$B$9,IF(C15="DBM",J15*'Mix Design'!$C$9,"")) | Q15: ='Job Planner'!P15 -> #VALUE! | R15: ='Job Planner'!Q15 -> #VALUE! | S15: ='Job Planner'!S15 -> #VALUE! | T15: ='Job Planner'!Z15 -> #VALUE! | U15: ='Job Planner'!AB15 -> #VALUE! | V15: ='Job Planner'!AE15 -> 0 | W15: ='Job Planner'!AF15 -> 0 | X15: ='Job Planner'!AG15 -> #VALUE! | AB15: =IF(OR(Z15="",AA15=""),"",SUMIFS($J$4:$J$203,$B$4:$B$203,Z15,$C$4:$C$203,AA15)) | AC15: =IF(OR(Z15="",AA15=""),"",SUMIFS($P$4:$P$203,$B$4:$B$203,Z15,$C$4:$C$203,AA15)) | AD15: =IF(OR(Z15="",AA15=""),"",SUMIFS($Q$4:$Q$203,$B$4:$B$203,Z15,$C$4:$C$203,AA15)) | AE15: =IF(OR(Z15="",AA15=""),"",SUMIFS($R$4:$R$203,$B$4:$B$203,Z15,$C$4:$C$203,AA15)) | AF15: =IF(OR(Z15="",AA15=""),"",SUMIFS($X$4:$X$203,$B$4:$B$203,Z15,$C$4:$C$203,AA15))
A16: ='Job Planner'!A16 -> 0 | B16: ='Job Planner'!B16 -> 0 | C16: ='Job Planner'!C16 -> 0 | D16: ='Job Planner'!D16 -> 0 | E16: =IF('Job Planner'!D16="GEOMETRY",'Job Planner'!E16,'Job Planner'!K16) | F16: ='Job Planner'!F16 -> 0 | G16: ='Job Planner'!G16 -> 0 | H16: ='Job Planner'!I16 | I16: ='Job Planner'!J16 | J16: ='Job Planner'!N16 -> #VALUE! | K16: =IF(C16="BC",J16*'Mix Design'!$B$4,IF(C16="DBM",J16*'Mix Design'!$C$4,"")) | L16: =IF(C16="BC",J16*'Mix Design'!$B$5,IF(C16="DBM",J16*'Mix Design'!$C$5,"")) | M16: =IF(C16="BC",J16*'Mix Design'!$B$6,IF(C16="DBM",J16*'Mix Design'!$C$6,"")) | N16: =IF(C16="BC",J16*'Mix Design'!$B$7,IF(C16="DBM",J16*'Mix Design'!$C$7,"")) | O16: =IF(C16="BC",J16*'Mix Design'!$B$8,IF(C16="DBM",J16*'Mix Design'!$C$8,"")) | P16: =IF(C16="BC",J16*'Mix Design'!$B$9,IF(C16="DBM",J16*'Mix Design'!$C$9,"")) | Q16: ='Job Planner'!P16 -> #VALUE! | R16: ='Job Planner'!Q16 -> #VALUE! | S16: ='Job Planner'!S16 -> #VALUE! | T16: ='Job Planner'!Z16 -> #VALUE! | U16: ='Job Planner'!AB16 -> #VALUE! | V16: ='Job Planner'!AE16 -> 0 | W16: ='Job Planner'!AF16 -> 0 | X16: ='Job Planner'!AG16 -> #VALUE! | AB16: =IF(OR(Z16="",AA16=""),"",SUMIFS($J$4:$J$203,$B$4:$B$203,Z16,$C$4:$C$203,AA16)) | AC16: =IF(OR(Z16="",AA16=""),"",SUMIFS($P$4:$P$203,$B$4:$B$203,Z16,$C$4:$C$203,AA16)) | AD16: =IF(OR(Z16="",AA16=""),"",SUMIFS($Q$4:$Q$203,$B$4:$B$203,Z16,$C$4:$C$203,AA16)) | AE16: =IF(OR(Z16="",AA16=""),"",SUMIFS($R$4:$R$203,$B$4:$B$203,Z16,$C$4:$C$203,AA16)) | AF16: =IF(OR(Z16="",AA16=""),"",SUMIFS($X$4:$X$203,$B$4:$B$203,Z16,$C$4:$C$203,AA16))
... A44: ='Job Planner'!A44 -> 0 | B44: ='Job Planner'!B44 -> 0 | C44: ='Job Planner'!C44 -> 0 | D44: ='Job Planner'!D44 -> 0 | E44: =IF('Job Planner'!D44="GEOMETRY",'Job Planner'!E44,'Job Planner'!K44) | F44: ='Job Planner'!F44 -> 0 | G44: ='Job Planner'!G44 -> 0 | H44: ='Job Planner'!I44 | I44: ='Job Planner'!J44 | J44: ='Job Planner'!N44 -> #VALUE! | K44: =IF(C44="BC",J44*'Mix Design'!$B$4,IF(C44="DBM",J44*'Mix Design'!$C$4,"")) | L44: =IF(C44="BC",J44*'Mix Design'!$B$5,IF(C44="DBM",J44*'Mix Design'!$C$5,"")) | M44: =IF(C44="BC",J44*'Mix Design'!$B$6,IF(C44="DBM",J44*'Mix Design'!$C$6,"")) | N44: =IF(C44="BC",J44*'Mix Design'!$B$7,IF(C44="DBM",J44*'Mix Design'!$C$7,"")) | O44: =IF(C44="BC",J44*'Mix Design'!$B$8,IF(C44="DBM",J44*'Mix Design'!$C$8,"")) | P44: =IF(C44="BC",J44*'Mix Design'!$B$9,IF(C44="DBM",J44*'Mix Design'!$C$9,"")) | Q44: ='Job Planner'!P44 -> #VALUE! | R44: ='Job Planner'!Q44 -> #VALUE! | S44: ='Job Planner'!S44 -> #VALUE! | T44: ='Job Planner'!Z44 -> #VALUE! | U44: ='Job Planner'!AB44 -> #VALUE! | V44: ='Job Planner'!AE44 -> 0 | W44: ='Job Planner'!AF44 -> 0 | X44: ='Job Planner'!AG44 -> #VALUE! | AB44: =IF(OR(Z44="",AA44=""),"",SUMIFS($J$4:$J$203,$B$4:$B$203,Z44,$C$4:$C$203,AA44)) | AC44: =IF(OR(Z44="",AA44=""),"",SUMIFS($P$4:$P$203,$B$4:$B$203,Z44,$C$4:$C$203,AA44)) | AD44: =IF(OR(Z44="",AA44=""),"",SUMIFS($Q$4:$Q$203,$B$4:$B$203,Z44,$C$4:$C$203,AA44)) | AE44: =IF(OR(Z44="",AA44=""),"",SUMIFS($R$4:$R$203,$B$4:$B$203,Z44,$C$4:$C$203,AA44)) | AF44: =IF(OR(Z44="",AA44=""),"",SUMIFS($X$4:$X$203,$B$4:$B$203,Z44,$C$4:$C$203,AA44))
A45: ='Job Planner'!A45 -> 0 | B45: ='Job Planner'!B45 -> 0 | C45: ='Job Planner'!C45 -> 0 | D45: ='Job Planner'!D45 -> 0 | E45: =IF('Job Planner'!D45="GEOMETRY",'Job Planner'!E45,'Job Planner'!K45) | F45: ='Job Planner'!F45 -> 0 | G45: ='Job Planner'!G45 -> 0 | H45: ='Job Planner'!I45 | I45: ='Job Planner'!J45 | J45: ='Job Planner'!N45 -> #VALUE! | K45: =IF(C45="BC",J45*'Mix Design'!$B$4,IF(C45="DBM",J45*'Mix Design'!$C$4,"")) | L45: =IF(C45="BC",J45*'Mix Design'!$B$5,IF(C45="DBM",J45*'Mix Design'!$C$5,"")) | M45: =IF(C45="BC",J45*'Mix Design'!$B$6,IF(C45="DBM",J45*'Mix Design'!$C$6,"")) | N45: =IF(C45="BC",J45*'Mix Design'!$B$7,IF(C45="DBM",J45*'Mix Design'!$C$7,"")) | O45: =IF(C45="BC",J45*'Mix Design'!$B$8,IF(C45="DBM",J45*'Mix Design'!$C$8,"")) | P45: =IF(C45="BC",J45*'Mix Design'!$B$9,IF(C45="DBM",J45*'Mix Design'!$C$9,"")) | Q45: ='Job Planner'!P45 -> #VALUE! | R45: ='Job Planner'!Q45 -> #VALUE! | S45: ='Job Planner'!S45 -> #VALUE! | T45: ='Job Planner'!Z45 -> #VALUE! | U45: ='Job Planner'!AB45 -> #VALUE! | V45: ='Job Planner'!AE45 -> 0 | W45: ='Job Planner'!AF45 -> 0 | X45: ='Job Planner'!AG45 -> #VALUE!
A46: ='Job Planner'!A46 -> 0 | B46: ='Job Planner'!B46 -> 0 | C46: ='Job Planner'!C46 -> 0 | D46: ='Job Planner'!D46 -> 0 | E46: =IF('Job Planner'!D46="GEOMETRY",'Job Planner'!E46,'Job Planner'!K46) | F46: ='Job Planner'!F46 -> 0 | G46: ='Job Planner'!G46 -> 0 | H46: ='Job Planner'!I46 | I46: ='Job Planner'!J46 | J46: ='Job Planner'!N46 -> #VALUE! | K46: =IF(C46="BC",J46*'Mix Design'!$B$4,IF(C46="DBM",J46*'Mix Design'!$C$4,"")) | L46: =IF(C46="BC",J46*'Mix Design'!$B$5,IF(C46="DBM",J46*'Mix Design'!$C$5,"")) | M46: =IF(C46="BC",J46*'Mix Design'!$B$6,IF(C46="DBM",J46*'Mix Design'!$C$6,"")) | N46: =IF(C46="BC",J46*'Mix Design'!$B$7,IF(C46="DBM",J46*'Mix Design'!$C$7,"")) | O46: =IF(C46="BC",J46*'Mix Design'!$B$8,IF(C46="DBM",J46*'Mix Design'!$C$8,"")) | P46: =IF(C46="BC",J46*'Mix Design'!$B$9,IF(C46="DBM",J46*'Mix Design'!$C$9,"")) | Q46: ='Job Planner'!P46 -> #VALUE! | R46: ='Job Planner'!Q46 -> #VALUE! | S46: ='Job Planner'!S46 -> #VALUE! | T46: ='Job Planner'!Z46 -> #VALUE! | U46: ='Job Planner'!AB46 -> #VALUE! | V46: ='Job Planner'!AE46 -> 0 | W46: ='Job Planner'!AF46 -> 0 | X46: ='Job Planner'!AG46 -> #VALUE!
A47: ='Job Planner'!A47 -> 0 | B47: ='Job Planner'!B47 -> 0 | C47: ='Job Planner'!C47 -> 0 | D47: ='Job Planner'!D47 -> 0 | E47: =IF('Job Planner'!D47="GEOMETRY",'Job Planner'!E47,'Job Planner'!K47) | F47: ='Job Planner'!F47 -> 0 | G47: ='Job Planner'!G47 -> 0 | H47: ='Job Planner'!I47 | I47: ='Job Planner'!J47 | J47: ='Job Planner'!N47 -> #VALUE! | K47: =IF(C47="BC",J47*'Mix Design'!$B$4,IF(C47="DBM",J47*'Mix Design'!$C$4,"")) | L47: =IF(C47="BC",J47*'Mix Design'!$B$5,IF(C47="DBM",J47*'Mix Design'!$C$5,"")) | M47: =IF(C47="BC",J47*'Mix Design'!$B$6,IF(C47="DBM",J47*'Mix Design'!$C$6,"")) | N47: =IF(C47="BC",J47*'Mix Design'!$B$7,IF(C47="DBM",J47*'Mix Design'!$C$7,"")) | O47: =IF(C47="BC",J47*'Mix Design'!$B$8,IF(C47="DBM",J47*'Mix Design'!$C$8,"")) | P47: =IF(C47="BC",J47*'Mix Design'!$B$9,IF(C47="DBM",J47*'Mix Design'!$C$9,"")) | Q47: ='Job Planner'!P47 -> #VALUE! | R47: ='Job Planner'!Q47 -> #VALUE! | S47: ='Job Planner'!S47 -> #VALUE! | T47: ='Job Planner'!Z47 -> #VALUE! | U47: ='Job Planner'!AB47 -> #VALUE! | V47: ='Job Planner'!AE47 -> 0 | W47: ='Job Planner'!AF47 -> 0 | X47: ='Job Planner'!AG47 -> #VALUE!
A48: ='Job Planner'!A48 -> 0 | B48: ='Job Planner'!B48 -> 0 | C48: ='Job Planner'!C48 -> 0 | D48: ='Job Planner'!D48 -> 0 | E48: =IF('Job Planner'!D48="GEOMETRY",'Job Planner'!E48,'Job Planner'!K48) | F48: ='Job Planner'!F48 -> 0 | G48: ='Job Planner'!G48 -> 0 | H48: ='Job Planner'!I48 | I48: ='Job Planner'!J48 | J48: ='Job Planner'!N48 -> #VALUE! | K48: =IF(C48="BC",J48*'Mix Design'!$B$4,IF(C48="DBM",J48*'Mix Design'!$C$4,"")) | L48: =IF(C48="BC",J48*'Mix Design'!$B$5,IF(C48="DBM",J48*'Mix Design'!$C$5,"")) | M48: =IF(C48="BC",J48*'Mix Design'!$B$6,IF(C48="DBM",J48*'Mix Design'!$C$6,"")) | N48: =IF(C48="BC",J48*'Mix Design'!$B$7,IF(C48="DBM",J48*'Mix Design'!$C$7,"")) | O48: =IF(C48="BC",J48*'Mix Design'!$B$8,IF(C48="DBM",J48*'Mix Design'!$C$8,"")) | P48: =IF(C48="BC",J48*'Mix Design'!$B$9,IF(C48="DBM",J48*'Mix Design'!$C$9,"")) | Q48: ='Job Planner'!P48 -> #VALUE! | R48: ='Job Planner'!Q48 -> #VALUE! | S48: ='Job Planner'!S48 -> #VALUE! | T48: ='Job Planner'!Z48 -> #VALUE! | U48: ='Job Planner'!AB48 -> #VALUE! | V48: ='Job Planner'!AE48 -> 0 | W48: ='Job Planner'!AF48 -> 0 | X48: ='Job Planner'!AG48 -> #VALUE!
A49: ='Job Planner'!A49 -> 0 | B49: ='Job Planner'!B49 -> 0 | C49: ='Job Planner'!C49 -> 0 | D49: ='Job Planner'!D49 -> 0 | E49: =IF('Job Planner'!D49="GEOMETRY",'Job Planner'!E49,'Job Planner'!K49) | F49: ='Job Planner'!F49 -> 0 | G49: ='Job Planner'!G49 -> 0 | H49: ='Job Planner'!I49 | I49: ='Job Planner'!J49 | J49: ='Job Planner'!N49 -> #VALUE! | K49: =IF(C49="BC",J49*'Mix Design'!$B$4,IF(C49="DBM",J49*'Mix Design'!$C$4,"")) | L49: =IF(C49="BC",J49*'Mix Design'!$B$5,IF(C49="DBM",J49*'Mix Design'!$C$5,"")) | M49: =IF(C49="BC",J49*'Mix Design'!$B$6,IF(C49="DBM",J49*'Mix Design'!$C$6,"")) | N49: =IF(C49="BC",J49*'Mix Design'!$B$7,IF(C49="DBM",J49*'Mix Design'!$C$7,"")) | O49: =IF(C49="BC",J49*'Mix Design'!$B$8,IF(C49="DBM",J49*'Mix Design'!$C$8,"")) | P49: =IF(C49="BC",J49*'Mix Design'!$B$9,IF(C49="DBM",J49*'Mix Design'!$C$9,"")) | Q49: ='Job Planner'!P49 -> #VALUE! | R49: ='Job Planner'!Q49 -> #VALUE! | S49: ='Job Planner'!S49 -> #VALUE! | T49: ='Job Planner'!Z49 -> #VALUE! | U49: ='Job Planner'!AB49 -> #VALUE! | V49: ='Job Planner'!AE49 -> 0 | W49: ='Job Planner'!AF49 -> 0 | X49: ='Job Planner'!AG49 -> #VALUE!
